Workbook

Sheet 00_使い方
A1: インバータ重量感度解析 Excel単体版 v3.2（VBAなし）
A4: 固定要求 | B4: 定格出力 P_out はアプリケーション側で決まる固定要求とし、感度ツリーの子ノードには配置しません。計算式では定数入力として参照します。
A5: 設計変数 | B5: V_dc、V_ll、f_sw、チップ面積、耐圧設計、電流密度、冷却流速、バスバー温度余裕、EMI遮断周波数など、設計余地がある変数を感度対象にします。
A6: 半導体深化 | B6: V_dc→必要耐圧→ドリフト層厚/ドーピング→比オン抵抗→R_on、およびチップ面積→R_on低下/C_oss増加/チップ重量増加を別経路で表現します。
A7: 感度 | B7: 局所弾性 ε を親式ごとに定義し、S_child=S_parent×ε でトップ重量まで伝播します。重量列は |S|×M_inv の感度等価重量です。
A8: トレードオフ | B8: 同一変数が複数経路に現れる場合、ダッシュボードで重量増加側・減少側・ネット感度を集計します。
A9: Level 12 | B9: 主要枝を最大Level 12まで深化しています。式右辺の変数は下位ノードの変数列に接続します。
A10: 位置付け | B10: 説明・デモ用の独立Excel版です。本流の要求仕様書・DB設計・プログラム版には影響させません。
A12: 式・係数は説明用簡易モデルです。半導体の耐圧―ドリフト層―オン抵抗―寄生容量などの物理関係は方向性とトレードオフをExcelで追跡するための近似です。実設計ではデバイスデータ/TCAD/損失マップへ置換してください。
A14: 入力体系 v1.1
A15: ① システム要求 | B15: 07_システム要求を入力
A16: ② シナリオ設計選択 | B16: 10_シナリオ入力の20項目だけ必要に応じ変更
A17: ③ 基準仕様 | B17: 09_基準仕様は材料/技術世代変更時のみ編集
A18: v2.2ダッシュボード | B18: 03_ダッシュボードは02_ツリーのQ=変数初出判定、R=変数連番から一意変数を自動表示します。通常QはCOUNTIF初出判定式。artifact_toolの文字列再計算不具合が出る6つの一意変数のみ、構造監査で唯一性を確認したうえでQを=1式としています（固定値手入力ではありません）。
A19: 感度計算経路 | B19: 主要計算経路は02_ツリーのParent ID、現在値F、説明式I、局所弾性J、正規化感度K、備考Nで追跡します。MAX/IF/トポロジー切替は式と備考に明示します。
A20: 互換性 | B20: ダッシュボード式はINDEX/MATCH/SUMIFS/AGGREGATEのみを使用し、スピル配列は不使用。
A21: v2.3 双方向GaN | B21: R038をmonolithic bidirectional GaNへ深化。CSIで別体逆阻止ダイオード削減、Ron/SW損失、dual-gate、substrate management、1200V適合、高周波化余地をモデル化。
A22: 評価方法 | B22: Enable_BD_GaNはCSI=1時のみ有効。Eon/Eoff/Eossが0ならk_BD_GaN_Esw_ratioを使用。高周波化余地は診断値でありf_swを自動変更しない。
A23: v3.0 | B23: 物理階層・二重計上・F式・J/K・研究将来技術・シート間参照・表示説明式を再監査。CSI/DCDC/LdcはDCDC機能と独立半導体段を分離し、同一Ldcを1回だけ計上。
A24: v3.1 | B24: v3.0後監査で検出したDPWM局所感度・表示経路とL重量係数J式を是正。DPWM C枝を局所展開し、Enableのシナリオ差分と連続パラメータ感度を分離。
A25: v3.2 | B25: Phase9最終回帰・残件解消を完了。Dashboard 468/468一致、Level自動計算整合、入力/基準仕様640件監査OK、主要シナリオ回帰、Structure/F/J/K/Level/cross-sheet/formula error監査を通過した最終リリース候補。

Sheet 01_入力仕様
A1: 01_入力仕様：固定要求・設計仕様・技術パラメータ | J1: システム推奨値 | K1: 自動計算/根拠 | L1: 適用区分 | M1: 手動上書き値 | N1: 新入力分類 | O1: 参照元 | P1: ユーザー操作 | Q1: 入力自動化備考
A4: 分類 | B4: 仕様 / 技術パラメータ | C4: 変数 | D4: 入力値 | E4: 単位 | F4: 主な影響先 | G4: 備考 | H4: 入力区分 | I4: 感度対象
A5: システム要求 | B5: 定格出力 | C5: P_out | D5: ='07_システム要求'!D9 -> 100 | E5: kW | F5: 電流・損失・容量 | G5: 上位アプリケーションで決定 | H5: 固定要求 | I5: 対象外 | J5: ='07_システム要求'!D9 -> 100 | K5: 上位システム定格出力 | L5: 自動 | M5: 100 | N5: システム要求→自動計算 | O5: 07_システム要求 | P5: システム要求のみ編集 | Q5: D列は直接編集せず参照元を編集
A6: 製品仕様 | B6: DCバス電圧 | C6: V_dc | D6: ='07_システム要求'!D13 -> 800 | E6: V | F6: 耐圧・Psw・Cdc・Idc・EMI | G6: 変更余地あり | H6: 設計変数 | I6: 対象 | J6: ='07_システム要求'!D13 -> 800 | K6: DCバス公称電圧 | L6: 自動 | M6: 800 | N6: システム要求→自動計算 | O6: 07_システム要求 | P6: システム要求のみ編集 | Q6: D列は直接編集せず参照元を編集
A7: 製品仕様 | B7: モータ線間電圧RMS | C7: V_ll | D7: ='07_システム要求'!D12 -> 400 | E7: V | F7: 相電流 | G7: モータ巻線構成等で変更余地 | H7: 設計変数 | I7: 対象 | J7: ='07_システム要求'!D12 -> 400 | K7: モータ最大線間電圧。モータ協調設計のため手動上書きを維持 | L7: 推奨のみ | M7: 400 | N7: システム要求→自動計算 | O7: 07_システム要求 | P7: システム要求のみ編集 | Q7: D列は直接編集せず参照元を編集
A8: 製品仕様 | B8: 力率 | C8: PF | D8: ='07_システム要求'!D14 -> 0.95 | E8: - | F8: 相電流 | G8: モータ/制御で改善余地 | H8: 設計変数 | I8: 対象 | J8: ='07_システム要求'!D14 -> 0.95 | K8: 目標力率 | L8: 自動 | M8: 0.95 | N8: システム要求→自動計算 | O8: 07_システム要求 | P8: システム要求のみ編集 | Q8: D列は直接編集せず参照元を編集
A9: 製品仕様 | B9: インバータ効率 | C9: eta | D9: ='07_システム要求'!D15 -> 0.97 | E9: - | F9: 相/DC電流 | G9: 簡易扱い | H9: 設計変数 | I9: 対象 | J9: ='07_システム要求'!D15 -> 0.97 | K9: 目標変換効率 | L9: 自動 | M9: 0.97 | N9: システム要求→自動計算 | O9: 07_システム要求 | P9: システム要求のみ編集 | Q9: D列は直接編集せず参照元を編集
A10: 製品仕様 | B10: スイッチング周波数 | C10: f_sw | D10: ='07_システム要求'!M10 -> 16000 | E10: Hz | F10: SW損失・EMI | G10: 主要トレードオフ | H10: 設計変数 | I10: 対象 | J10: ='07_システム要求'!M10 -> 16000 | K10: 最高電気周波数×最低PWM回数。可聴域回避要求も考慮 | L10: 自動 | M10: 10000 | N10: システム要求→自動計算 | O10: 07_システム要求 | P10: システム要求のみ編集 | Q10: D列は直接編集せず参照元を編集
A11: 製品仕様 | B11: 許容DC電圧リップル率 | C11: r_vdc | D11: ='09_基準仕様'!E9 -> 0.05 | E11: - | F11: C_req | G11: DCリンク電圧リップル許容値5%を基準設計値として採用。物理定数ではなくC_reqを決めるシステム設計要求。実機のDCバス品質要求に合わせて変更する。 | H11: 設計変数 | I11: 対象 | N11: 基準仕様（シナリオ間固定） | O11: 09_基準仕様 | P11: 通常は編集しない | Q11: D列は直接編集せず参照元を編集
A12: 製品仕様 | B12: DCリンクバッファ時間 | C12: t_buf | D12: ='09_基準仕様'!E10 -> 0.0005 | E12: s | F12: C_req | G12: DCリンクCのエネルギーバッファ時間0.5 msを基準設計値として採用。物理定数ではなくC_reqを決める簡略設計仮定。負荷過渡/制御帯域の要求で校正する。 | H12: 設計変数 | I12: 対象 | N12: 基準仕様（シナリオ間固定） | O12: 09_基準仕様 | P12: 通常は編集しない | Q12: D列は直接編集せず参照元を編集
A13: 半導体 | B13: パワーデバイス総数 | C13: N_power_device_total | D13: ='07_システム要求'!M24 -> 6 | E13: 個 | F13: M_semi/P_sw | G13: トポロジー自動算出 | H13: 設計変数 | I13: 対象 | N13: システム要求→自動計算 | O13: 07_システム要求 | P13: 通常は直接編集しない | Q13: VSIトポロジー/CSIから自動算出
A14: 半導体 | B14: DC電圧→必要耐圧係数 | C14: K_vblk | D14: 1 | E14: - | F14: V_block_req | G14: 2L-VSI/CSIでは K_vblk×Vdc+surge。3L-NPC/ANPCでは Vdc/2+surge とし、K_vblkは3L枝に適用しない。 | H14: 技術係数 | I14: 対象 | N14: 基準仕様（シナリオ間固定） | O14: 09_基準仕様 | P14: 通常は編集しない | Q14: D列は直接編集せず参照元を編集
A15: 半導体 | B15: ドリフト層電界利用率 | C15: k_Euse | D15: ='09_基準仕様'!E13 -> 0.72 | E15: - | F15: E_allow | G15: 材料臨界電界E_critをそのまま使わず72%に制限する設計利用率。欠陥・温度・電界集中・信頼性余裕をまとめた簡略係数で、普遍定数ではない。 | H15: 技術係数 | I15: 対象 | N15: 基準仕様（シナリオ間固定） | O15: 09_基準仕様 | P15: 通常は編集しない | Q15: D列は直接編集せず参照元を編集
A16: 半導体 | B16: 材料臨界電界 | C16: E_crit | D16: ='09_基準仕様'!E14 -> 250000000 | E16: V/m | F16: E_allow | G16: 4H-SiCの臨界電界の代表値として2.5 MV/cm (=2.5×10^8 V/m)を採用。結晶方位・ドーピング・温度で変化するため、設計余裕は別変数k_Euseで与える。参考: https://repository.kulib.kyoto-u.ac.jp/dspace/bitstream/2433/288729/1/dkogk05254.pdf | H16: 材料 | I16: 対象 | N16: 基準仕様（シナリオ間固定） | O16: 09_基準仕様 | P16: 通常は編集しない | Q16: D列は直接編集せず参照元を編集
A17: 半導体 | B17: ドリフト層厚余裕係数 | C17: K_tdrift | D17: ='09_基準仕様'!E15 -> 1.15 | E17: - | F17: t_drift | G17: 理想ドリフト層厚に15%余裕を持たせる簡略安全係数。端部電界・製造ばらつき等をまとめた設計仮定で、デバイス実測/TCADで校正する。 | H17: 技術係数 | I17: 対象 | N17: 基準仕様（シナリオ間固定） | O17: 09_基準仕様 | P17: 通常は編集しない | Q17: D列は直接編集せず参照元を編集
A18: 半導体 | B18: 基準ドーピング濃度 | C18: N_d_ref | D18: ='09_基準仕様'!E16 -> 8e+21 | E18: 1/m³ | F18: N_drift | G18: 説明用 | H18: 材料 | I18: 対象 | N18: 基準仕様（シナリオ間固定） | O18: 09_基準仕様 | P18: 通常は編集しない | Q18: D列は直接編集せず参照元を編集
A19: 半導体 | B19: 耐圧基準 | C19: V_ref_nd | D19: ='09_基準仕様'!E17 -> 1200 | E19: V | F19: N_drift | G19: ドリフト層ドーピングの正規化基準として1200 Vを採用。物理定数ではなく比率式の基準点。1200 V級SiCデバイスを基準にしたモデル正規化値。 | H19: 技術係数 | I19: 対象 | N19: 基準仕様（シナリオ間固定） | O19: 09_基準仕様 | P19: 通常は編集しない | Q19: D列は直接編集せず参照元を編集
A20: 半導体 | B20: ドーピング耐圧指数 | C20: a_nd | D20: ='09_基準仕様'!E18 -> 1.2 | E20: - | F20: N_drift | G20: N∝V^-a | H20: 技術係数 | I20: 対象 | N20: 基準仕様（シナリオ間固定） | O20: 09_基準仕様 | P20: 通常は編集しない | Q20: D列は直接編集せず参照元を編集
A21: 半導体 | B21: 電子移動度 | C21: mu_n | D21: ='09_基準仕様'!E19 -> 0.08 | E21: m²/(V·s) | F21: rho_drift | G21: 説明用SiC | H21: 材料 | I21: 対象 | N21: 基準仕様（シナリオ間固定） | O21: 09_基準仕様 | P21: 通常は編集しない | Q21: D列は直接編集せず参照元を編集
A22: 半導体 | B22: 素電荷 | C22: q_e | D22: ='09_基準仕様'!E20 -> 1.602e-19 | E22: C | F22: rho_drift | G22: 物理定数 | H22: 固定定数 | I22: 対象外 | N22: 基準仕様（シナリオ間固定） | O22: 09_基準仕様 | P22: 通常は編集しない | Q22: D列は直接編集せず参照元を編集
A23: 半導体 | B23: 比オン抵抗補正係数 | C23: K_rsp | D23: ='09_基準仕様'!E21 -> 1 | E23: - | F23: Rsp_drift | G23: 比オン抵抗簡略式の補正係数。初期値1.0は基準モデルをそのまま用いる意味で、実デバイスR_on,spとの比較で校正する。 | H23: 技術係数 | I23: 対象 | N23: 基準仕様（シナリオ間固定） | O23: 09_基準仕様 | P23: 通常は編集しない | Q23: D列は直接編集せず参照元を編集
A24: 半導体 | B24: セル/コンタクト抵抗面積積 | C24: Rsp_cell | D24: ='09_基準仕様'!E22 -> 0.0015 | E24: Ω·mm² | F24: Rsp_total | G24: 説明用 | H24: 技術係数 | I24: 対象 | N24: 基準仕様（シナリオ間固定） | O24: 09_基準仕様 | P24: 通常は編集しない | Q24: D列は直接編集せず参照元を編集
A25: 半導体 | B25: チップ面積 | C25: A_chip | D25: ='09_基準仕様'!E23 -> 100 | E25: mm² | F25: Ron,Coss,m_chip | G25: 主要トレードオフ | H25: 設計変数 | I25: 対象 | J25: ='07_システム要求'!M15 -> 100 | K25: 現製品基準のチップ面積スケーリング。探索変数なので固定しない | L25: 推奨のみ | M25: 100 | N25: 基準仕様（シナリオ間固定） | O25: 09_基準仕様 | P25: 通常は編集しない | Q25: D列は直接編集せず参照元を編集
A26: 半導体 | B26: チップ厚さ | C26: t_chip | D26: ='09_基準仕様'!E24 -> 0.18 | E26: mm | F26: m_chip | G26: パワー半導体チップの基準厚さ0.18 mm。物理定数ではなく重量換算用の設計値で、実採用ウェハ/ダイ厚に置換する。 | H26: 設計変数 | I26: 対象 | N26: 基準仕様（シナリオ間固定） | O26: 09_基準仕様 | P26: 通常は編集しない | Q26: D列は直接編集せず参照元を編集
A27: 半導体 | B27: チップ密度 | C27: rho_chip | D27: ='09_基準仕様'!E25 -> 3210 | E27: kg/m³ | F27: m_chip | G27: SiC | H27: 材料 | I27: 対象 | N27: 基準仕様（シナリオ間固定） | O27: 09_基準仕様 | P27: 通常は編集しない | Q27: D列は直接編集せず参照元を編集
A28: 半導体 | B28: 出力容量面積係数 | C28: Coss_area_ref | D28: ='09_基準仕様'!E26 -> 0.0051788079 | E28: nF/mm² | F28: Coss | G28: 説明用 | H28: 技術係数 | I28: 対象 | N28: 基準仕様（シナリオ間固定） | O28: 09_基準仕様 | P28: 通常は編集しない | Q28: D列は直接編集せず参照元を編集
A29: 半導体 | B29: 容量耐圧指数 | C29: b_coss | D29: ='09_基準仕様'!E27 -> 0.35 | E29: - | F29: Coss | G29: Coss∝V^-b | H29: 技術係数 | I29: 対象 | N29: 基準仕様（シナリオ間固定） | O29: 09_基準仕様 | P29: 通常は編集しない | Q29: D列は直接編集せず参照元を編集
A30: 半導体 | B30: 容量耐圧基準 | C30: V_ref_coss | D30: ='09_基準仕様'!E28 -> 1200 | E30: V | F30: Coss | G30: Cossの耐圧依存を正規化する基準電圧1200 V。物理定数ではなく1200 V級デバイスを基準にしたモデル係数。 | H30: 技術係数 | I30: 対象 | N30: 基準仕様（シナリオ間固定） | O30: 09_基準仕様 | P30: 通常は編集しない | Q30: D列は直接編集せず参照元を編集
A31: 半導体 | B31: スイッチングエネルギー容量係数 | C31: K_esw | D31: ='09_基準仕様'!E29 -> 1 | E31: - | F31: E_sw | G31: 0.5CV²簡略化 | H31: 技術係数 | I31: 対象 | N31: 基準仕様（シナリオ間固定） | O31: 09_基準仕様 | P31: 通常は編集しない | Q31: D列は直接編集せず参照元を編集
A32: 半導体 | B32: チップ数係数 | C32: k_chip | D32: ='09_基準仕様'!E30 -> 1.25 | E32: - | F32: N_chip_mod | G32: 電流分担・温度・信頼性余裕を含め、理論必要チップ数へ25%余裕を与える簡略係数。実デバイスSOA/熱設計で校正する。 | H32: 技術係数 | I32: 対象 | N32: 基準仕様（シナリオ間固定） | O32: 09_基準仕様 | P32: 通常は編集しない | Q32: D列は直接編集せず参照元を編集
A33: 半導体 | B33: チップ許容電流密度 | C33: J_chip | D33: ='09_基準仕様'!E31 -> 1.15 | E33: A/mm² | F33: I_chip | G33: チップ面積推定用の基準電流密度1.15 A/mm²。物理定数ではなく100 kW級の一次面積見積り用設計仮定。採用チップの定格電流・実効面積で必ず校正する。 | H33: 設計変数 | I33: 対象 | N33: 基準仕様（シナリオ間固定） | O33: 09_基準仕様 | P33: 通常は編集しない | Q33: D列は直接編集せず参照元を編集
A34: 半導体 | B34: チップ有効面積率 | C34: k_active | D34: ='09_基準仕様'!E32 -> 0.72 | E34: - | F34: A_active | G34: ダイ外形面積に対する有効通電領域72%の簡略仮定。端部終端・ゲート/パッド領域を除外する面積利用率で、レイアウト実測で校正する。 | H34: 技術係数 | I34: 対象 | N34: 基準仕様（シナリオ間固定） | O34: 09_基準仕様 | P34: 通常は編集しない | Q34: D列は直接編集せず参照元を編集
A35: 半導体 | B35: DBC面積 | C35: A_dbc | D35: ='09_基準仕様'!E33 -> 4200 | E35: mm² | F35: m_dbc | G35: 100 kW級基準モデルのDBC面積として置いた初期設計値。物理定数ではない。m_dbcの一次見積り用で、実機BOM・CAD・採用部品データに置換/校正する。 | H35: 設計変数 | I35: 対象 | N35: 基準仕様（シナリオ間固定） | O35: 09_基準仕様 | P35: 通常は編集しない | Q35: D列は直接編集せず参照元を編集
A36: 半導体 | B36: DBC等価厚さ | C36: t_dbc | D36: ='09_基準仕様'!E34 -> 0.92 | E36: mm | F36: m_dbc | G36: 100 kW級基準モデルのDBC等価厚さとして置いた初期設計値。物理定数ではない。m_dbcの一次見積り用で、実機BOM・CAD・採用部品データに置換/校正する。 | H36: 設計変数 | I36: 対象 | N36: 基準仕様（シナリオ間固定） | O36: 09_基準仕様 | P36: 通常は編集しない | Q36: D列は直接編集せず参照元を編集
A37: 半導体 | B37: DBC等価密度 | C37: rho_dbc | D37: ='09_基準仕様'!E35 -> 4000 | E37: kg/m³ | F37: m_dbc | G37: Cu/セラミック/Cu積層を一体化した等価密度4,000 kg/m³。Cu≈8,960 kg/m³、AlN≈3,260 kg/m³と層厚から見て妥当なオーダーの簡略値。実層厚で再計算する。 | H37: 材料 | I37: 対象 | N37: 基準仕様（シナリオ間固定） | O37: 09_基準仕様 | P37: 通常は編集しない | Q37: D列は直接編集せず参照元を編集
... A59: バスバー | B59: 許容導体温度 | C59: T_bus_max | D59: ='09_基準仕様'!E57 -> 105 | E59: °C | F59: dT_bus | G59: バスバー導体の許容温度105°Cを基準設計値として採用。絶縁材・周囲温度・接続部定格により変更する。 | H59: 設計変数 | I59: 対象 | N59: 基準仕様（シナリオ間固定） | O59: 09_基準仕様 | P59: 通常は編集しない | Q59: D列は直接編集せず参照元を編集
A60: バスバー | B60: 周囲温度 | C60: T_amb | D60: ='07_システム要求'!D18 -> 45 | E60: °C | F60: dT_bus | G60: 外部条件 | H60: 外部条件 | I60: 対象 | J60: ='07_システム要求'!D18 -> 45 | K60: システム最大周囲温度 | L60: 自動 | M60: 45 | N60: システム要求→自動計算 | O60: 07_システム要求 | P60: システム要求のみ編集 | Q60: D列は直接編集せず参照元を編集
A61: バスバー | B61: 基準温度上昇 | C61: dT_bus_ref | D61: ='09_基準仕様'!E58 -> 60 | E61: K | F61: J_bus | G61: バスバー電流密度補正式の基準温度上昇60 K。物理定数ではなく熱設計の正規化値。 | H61: 技術係数 | I61: 対象 | N61: 基準仕様（シナリオ間固定） | O61: 09_基準仕様 | P61: 通常は編集しない | Q61: D列は直接編集せず参照元を編集
A62: バスバー | B62: 放熱改善係数 | C62: k_bus_cool | D62: ='09_基準仕様'!E59 -> 1 | E62: - | F62: J_bus | G62: バスバー放熱改善の補正係数。1.0は基準冷却条件、放熱構造変更時に実測/熱解析で校正する。 | H62: 技術係数 | I62: 対象 | N62: 基準仕様（シナリオ間固定） | O62: 09_基準仕様 | P62: 通常は編集しない | Q62: D列は直接編集せず参照元を編集
A63: バスバー | B63: 導体総長 | C63: L_bus | D63: ='09_基準仕様'!E60 -> 1.2 | E63: m | F63: m_bus | G63: 100 kW級基準モデルの導体総長として置いた初期設計値。物理定数ではない。m_busの一次見積り用で、実機BOM・CAD・採用部品データに置換/校正する。 | H63: 設計変数 | I63: 対象 | N63: 基準仕様（シナリオ間固定） | O63: 09_基準仕様 | P63: 通常は編集しない | Q63: D列は直接編集せず参照元を編集
...

Sheet 02_ツリー
A1: 02_ツリー：Level 12 技術分解 / 設計変数 / 等価重量 / 感度
A4: Node ID | B4: Parent ID | C4: Level（式） | D4: 項目名 | E4: 変数 | F4: 現在値 | G4: 単位 | H4: 重量 [kg] | I4: 式（左辺 = 右辺） | J4: 局所弾性 ε | K4: 正規化感度 S | L4: 感度方向 | M4: 変更可否 | N4: 備考 | O4: 最終変数判定 1=最下層 / 0=途中 | P4: Enable単純比例局所弾性 ε 直接追加/削除枝 | Q4: 変数初出判定 | R4: 変数連番
A5: T001 | C5: 0 | D5: インバータ総重量 | E5: M_inv | F5: =F6+F34+F96+F111+F129+F140+F174+F175+F176+F177+F561+F186+F355+F600 -> 12.438076 | G5: kg | H5: =ABS(K5)*$F$5 -> 12.438076 | I5: M_inv=M_semi+M_cool+M_dc_cap+M_bus+M_case+M_emi+M_ctrl+M_sensor+M_conn+M_other+M_DCDC+M_ss+M_snub+M_APD | J5: =1 -> 1 | K5: =1 -> 1 | L5: TOP KPI | M5: 設計対象 | N5: トップKPI。Root直下は相互に重量を重複計上しない物理サブシステム/独立追加回路のみ。 | O5: =IF($A5="","",--(COUNTIF($B$5:$B$679,$A5)=0)) -> 0 | Q5: =IF(E5="","",--(MATCH(E5,$E$5:$E$560,0)=ROW()-4)) -> 1 | R5: =IF(Q5=1,COUNTIF($Q$5:Q5,1),"") -> 1
A6: T002 | B6: T001 | C6: 1 | D6: パワー半導体・モジュール関連重量 | E6: M_semi | F6: =F7*F8+F178 -> 1.6469356 | G6: kg | H6: =ABS(K6)*$F$5 -> 1.6469356 | I6: M_semi=N_power_device_total×m_mod+M_parallel | J6: =F6/F5 -> 0.1324108 | K6: =K5*J6 -> 0.1324108 | L6: =IF(K6>0,"増加→総重量増",IF(K6<0,"増加→総重量減","中立")) -> 増加→総重量増 | M6: 設計対象 | N6: 主半導体総重量。N_power_device_totalには方式に応じた追加直列ダイオード数を含め、現簡易モデルでは同一m_modで等価質量化する。CSI直列ダイオード重量を別枝で再加算しない。詳細パッケージ分解時にSW/diode単体質量へ置換。 | O6: =IF($A6="","",--(COUNTIF($B$5:$B$679,$A6)=0)) -> 0 | Q6: =IF(E6="","",--(MATCH(E6,$E$5:$E$560,0)=ROW()-4)) -> 1 | R6: =IF(Q6=1,COUNTIF($Q$5:Q6,1),"") -> 2
A7: T003 | B7: T002 | C7: 2 | D7: パワーデバイス総数 | E7: N_power_device_total | F7: ='01_入力仕様'!D13 -> 6 | G7: 個 | H7: =ABS(K7)*$F$5 -> 1.0169356 | I7: 入力仕様 | J7: =('01_入力仕様'!D13*F8)/F6 -> 0.61747138 | K7: =K6*J7 -> 0.081759879 | L7: =IF(K7>0,"増加→総重量増",IF(K7<0,"増加→総重量減","中立")) -> 増加→総重量増 | M7: 設計対象 | N7: 2L=6、NPC=18(12SW+6diode)、ANPC=18SW、CSI=12(6SW+6逆阻止diode)。 | O7: =IF($A7="","",--(COUNTIF($B$5:$B$679,$A7)=0)) -> 1 | Q7: =IF(E7="","",--(MATCH(E7,$E$5:$E$560,0)=ROW()-4)) -> 1 | R7: =IF(Q7=1,COUNTIF($Q$5:Q7,1),"") -> 3
A8: T004 | B8: T002 | C8: 2 | D8: 1モジュール重量 | E8: m_mod | F8: =F9+F25+F29+F33 -> 0.16948927 | G8: kg | H8: =ABS(K8)*$F$5 -> 1.0169356 | I8: m_mod=m_chip_mod+m_dbc+m_base+m_pkg | J8: =('01_入力仕様'!D13*F8)/F6 -> 0.61747138 | K8: =K6*J8 -> 0.081759879 | L8: =IF(K8>0,"増加→総重量増",IF(K8<0,"増加→総重量減","中立")) -> 増加→総重量増 | M8: 設計対象 | O8: =IF($A8="","",--(COUNTIF($B$5:$B$679,$A8)=0)) -> 0 | Q8: =IF(E8="","",--(MATCH(E8,$E$5:$E$560,0)=ROW()-4)) -> 1 | R8: =IF(Q8=1,COUNTIF($Q$5:Q8,1),"") -> 4
A9: T005 | B9: T004 | C9: 3 | D9: チップ重量/モジュール | E9: m_chip_mod | F9: =F10*F21 -> 0.00013662849 | G9: kg | H9: =ABS(K9)*$F$5 -> 0.00081977092 | I9: m_chip_mod=N_chip_mod×m_chip | J9: =F9/F8 -> 0.0008061188 | K9: =K8*J9 -> 6.5908176e-05 | L9: =IF(K9>0,"増加→総重量増",IF(K9<0,"増加→総重量減","中立")) -> 増加→総重量増 | M9: 設計対象 | O9: =IF($A9="","",--(COUNTIF($B$5:$B$679,$A9)=0)) -> 0 | Q9: =IF(E9="","",--(MATCH(E9,$E$5:$E$560,0)=ROW()-4)) -> 1 | R9: =IF(Q9=1,COUNTIF($Q$5:Q9,1),"") -> 5
A10: T006 | B10: T005 | C10: 4 | D10: チップ数/モジュール | E10: N_chip_mod | F10: =F11*F12/F16 -> 2.3646328 | G10: 個 | H10: =ABS(K10)*$F$5 -> 0.00081977092 | I10: N_chip_mod=k_chip×I_phase/I_chip | J10: =1 -> 1 | K10: =K9*J10 -> 6.5908176e-05 | L10: =IF(K10>0,"増加→総重量増",IF(K10<0,"増加→総重量減","中立")) -> 増加→総重量増 | M10: 設計対象 | O10: =IF($A10="","",--(COUNTIF($B$5:$B$679,$A10)=0)) -> 0 | Q10: =IF(E10="","",--(MATCH(E10,$E$5:$E$560,0)=ROW()-4)) -> 1 | R10: =IF(Q10=1,COUNTIF($Q$5:Q10,1),"") -> 6
A11: T007 | B11: T006 | C11: 5 | D11: チップ数係数 | E11: k_chip | F11: ='01_入力仕様'!D32 -> 1.25 | G11: - | H11: =ABS(K11)*$F$5 -> 0.00081977092 | I11: 入力仕様 | J11: =1 -> 1 | K11: =K10*J11 -> 6.5908176e-05 | L11: =IF(K11>0,"増加→総重量増",IF(K11<0,"増加→総重量減","中立")) -> 増加→総重量増 | M11: 設計対象 | O11: =IF($A11="","",--(COUNTIF($B$5:$B$679,$A11)=0)) -> 1 | Q11: =IF(E11="","",--(MATCH(E11,$E$5:$E$560,0)=ROW()-4)) -> 1 | R11: =IF(Q11=1,COUNTIF($Q$5:Q11,1),"") -> 7
A12: T008 | B12: T006 | C12: 5 | D12: 相電流RMS | E12: I_phase | F12: ='01_入力仕様'!D5*1000/(SQRT(3)*F13*F14*F15) -> 156.63328 | G12: A | H12: =ABS(K12)*$F$5 -> 0.00081977092 | I12: I_phase=P_out_const/(√3×V_ll×PF×eta) | J12: =1 -> 1 | K12: =K10*J12 -> 6.5908176e-05 | L12: =IF(K12>0,"増加→総重量増",IF(K12<0,"増加→総重量減","中立")) -> 増加→総重量増 | M12: 設計対象 | N12: P_outは固定要求で子ノード化しない | O12: =IF($A12="","",--(COUNTIF($B$5:$B$679,$A12)=0)) -> 0 | Q12: =IF(E12="","",--(MATCH(E12,$E$5:$E$560,0)=ROW()-4)) -> 1 | R12: =IF(Q12=1,COUNTIF($Q$5:Q12,1),"") -> 8
A13: T009 | B13: T008 | C13: 6 | D13: 線間電圧RMS | E13: V_ll | F13: ='01_入力仕様'!D7 -> 400 | G13: V | H13: =ABS(K13)*$F$5 -> 0.00081977092 | I13: 入力仕様 | J13: =-1 -> -1 | K13: =K12*J13 -> -6.5908176e-05 | L13: =IF(K13>0,"増加→総重量増",IF(K13<0,"増加→総重量減","中立")) -> 増加→総重量減 | M13: 設計対象 | O13: =IF($A13="","",--(COUNTIF($B$5:$B$679,$A13)=0)) -> 1 | Q13: =IF(E13="","",--(MATCH(E13,$E$5:$E$560,0)=ROW()-4)) -> 1 | R13: =IF(Q13=1,COUNTIF($Q$5:Q13,1),"") -> 9
A14: T010 | B14: T008 | C14: 6 | D14: 力率 | E14: PF | F14: ='01_入力仕様'!D8 -> 0.95 | G14: - | H14: =ABS(K14)*$F$5 -> 0.00081977092 | I14: 入力仕様 | J14: =-1 -> -1 | K14: =K12*J14 -> -6.5908176e-05 | L14: =IF(K14>0,"増加→総重量増",IF(K14<0,"増加→総重量減","中立")) -> 増加→総重量減 | M14: 設計対象 | O14: =IF($A14="","",--(COUNTIF($B$5:$B$679,$A14)=0)) -> 1 | Q14: =IF(E14="","",--(MATCH(E14,$E$5:$E$560,0)=ROW()-4)) -> 1 | R14: =IF(Q14=1,COUNTIF($Q$5:Q14,1),"") -> 10
A15: T011 | B15: T008 | C15: 6 | D15: 効率 | E15: eta | F15: ='01_入力仕様'!D9 -> 0.97 | G15: - | H15: =ABS(K15)*$F$5 -> 0.00081977092 | I15: 入力仕様 | J15: =-1 -> -1 | K15: =K12*J15 -> -6.5908176e-05 | L15: =IF(K15>0,"増加→総重量増",IF(K15<0,"増加→総重量減","中立")) -> 増加→総重量減 | M15: 設計対象 | O15: =IF($A15="","",--(COUNTIF($B$5:$B$679,$A15)=0)) -> 1 | Q15: =IF(E15="","",--(MATCH(E15,$E$5:$E$560,0)=ROW()-4)) -> 1 | R15: =IF(Q15=1,COUNTIF($Q$5:Q15,1),"") -> 11
A16: T012 | B16: T006 | C16: 5 | D16: 1チップ電流能力 | E16: I_chip | F16: =F17*F18 -> 82.8 | G16: A | H16: =ABS(K16)*$F$5 -> 0.00081977092 | I16: I_chip=J_chip×A_active | J16: =-1 -> -1 | K16: =K10*J16 -> -6.5908176e-05 | L16: =IF(K16>0,"増加→総重量増",IF(K16<0,"増加→総重量減","中立")) -> 増加→総重量減 | M16: 設計対象 | O16: =IF($A16="","",--(COUNTIF($B$5:$B$679,$A16)=0)) -> 0 | Q16: =IF(E16="","",--(MATCH(E16,$E$5:$E$560,0)=ROW()-4)) -> 1 | R16: =IF(Q16=1,COUNTIF($Q$5:Q16,1),"") -> 12
A17: T013 | B17: T012 | C17: 6 | D17: 実効チップ許容電流密度 | E17: J_chip_eff | F17: ='01_入力仕様'!D33*F538 -> 1.15 | G17: A/mm² | H17: =ABS(K17)*$F$5 -> 0.00081977092 | I17: J_chip_eff=J_chip×k_pkg_J | J17: =1 -> 1 | K17: =K16*J17 -> -6.5908176e-05 | L17: =IF(K17>0,"増加→総重量増",IF(K17<0,"増加→総重量減","中立")) -> 増加→総重量減 | M17: 設計対象 | O17: =IF($A17="","",--(COUNTIF($B$5:$B$679,$A17)=0)) -> 0 | Q17: =IF(E17="","",--(MATCH(E17,$E$5:$E$560,0)=ROW()-4)) -> 1 | R17: =IF(Q17=1,COUNTIF($Q$5:Q17,1),"") -> 13
A18: T014 | B18: T012 | C18: 6 | D18: 有効チップ面積 | E18: A_active | F18: =F19*F20 -> 72 | G18: mm² | H18: =ABS(K18)*$F$5 -> 0.00081977092 | I18: A_active=k_active×A_chip | J18: =1 -> 1 | K18: =K16*J18 -> -6.5908176e-05 | L18: =IF(K18>0,"増加→総重量増",IF(K18<0,"増加→総重量減","中立")) -> 増加→総重量減 | M18: 設計対象 | O18: =IF($A18="","",--(COUNTIF($B$5:$B$679,$A18)=0)) -> 0 | Q18: =IF(E18="","",--(MATCH(E18,$E$5:$E$560,0)=ROW()-4)) -> 1 | R18: =IF(Q18=1,COUNTIF($Q$5:Q18,1),"") -> 14
A19: T015 | B19: T014 | C19: 7 | D19: 有効面積率 | E19: k_active | F19: ='01_入力仕様'!D34 -> 0.72 | G19: - | H19: =ABS(K19)*$F$5 -> 0.00081977092 | I19: 入力仕様 | J19: =1 -> 1 | K19: =K18*J19 -> -6.5908176e-05 | L19: =IF(K19>0,"増加→総重量増",IF(K19<0,"増加→総重量減","中立")) -> 増加→総重量減 | M19: 設計対象 | O19: =IF($A19="","",--(COUNTIF($B$5:$B$679,$A19)=0)) -> 1 | Q19: =IF(E19="","",--(MATCH(E19,$E$5:$E$560,0)=ROW()-4)) -> 1 | R19: =IF(Q19=1,COUNTIF($Q$5:Q19,1),"") -> 15
A20: T016 | B20: T014 | C20: 7 | D20: チップ面積 | E20: A_chip | F20: ='01_入力仕様'!D25 -> 100 | G20: mm² | H20: =ABS(K20)*$F$5 -> 0.00081977092 | I20: 入力仕様 | J20: =1 -> 1 | K20: =K18*J20 -> -6.5908176e-05 | L20: =IF(K20>0,"増加→総重量増",IF(K20<0,"増加→総重量減","中立")) -> 増加→総重量減 | M20: 設計対象 | N20: 面積増→電流能力増 | O20: =IF($A20="","",--(COUNTIF($B$5:$B$679,$A20)=0)) -> 1 | Q20: =IF(E20="","",--(MATCH(E20,$E$5:$E$560,0)=ROW()-4)) -> 1 | R20: =IF(Q20=1,COUNTIF($Q$5:Q20,1),"") -> 16
A21: T017 | B21: T005 | C21: 4 | D21: 1チップ重量 | E21: m_chip | F21: =F22*F23*F24*0.000000001 -> 5.778e-05 | G21: kg | H21: =ABS(K21)*$F$5 -> 0.00081977092 | I21: m_chip=A_chip×t_chip×rho_chip×1E-9 | J21: =1 -> 1 | K21: =K9*J21 -> 6.5908176e-05 | L21: =IF(K21>0,"増加→総重量増",IF(K21<0,"増加→総重量減","中立")) -> 増加→総重量増 | M21: 設計対象 | O21: =IF($A21="","",--(COUNTIF($B$5:$B$679,$A21)=0)) -> 0 | Q21: =IF(E21="","",--(MATCH(E21,$E$5:$E$560,0)=ROW()-4)) -> 1 | R21: =IF(Q21=1,COUNTIF($Q$5:Q21,1),"") -> 17
A22: T018 | B22: T017 | C22: 5 | D22: チップ面積 | E22: A_chip | F22: ='01_入力仕様'!D25 -> 100 | G22: mm² | H22: =ABS(K22)*$F$5 -> 0.00081977092 | I22: 入力仕様 | J22: =1 -> 1 | K22: =K21*J22 -> 6.5908176e-05 | L22: =IF(K22>0,"増加→総重量増",IF(K22<0,"増加→総重量減","中立")) -> 増加→総重量増 | M22: 設計対象 | N22: 面積増→重量増 | O22: =IF($A22="","",--(COUNTIF($B$5:$B$679,$A22)=0)) -> 1 | Q22: =IF(E22="","",--(MATCH(E22,$E$5:$E$560,0)=ROW()-4)) -> 0 | R22: =IF(Q22=1,COUNTIF($Q$5:Q22,1),"")
A23: T019 | B23: T017 | C23: 5 | D23: チップ厚さ | E23: t_chip | F23: ='01_入力仕様'!D26 -> 0.18 | G23: mm | H23: =ABS(K23)*$F$5 -> 0.00081977092 | I23: 入力仕様 | J23: =1 -> 1 | K23: =K21*J23 -> 6.5908176e-05 | L23: =IF(K23>0,"増加→総重量増",IF(K23<0,"増加→総重量減","中立")) -> 増加→総重量増 | M23: 設計対象 | O23: =IF($A23="","",--(COUNTIF($B$5:$B$679,$A23)=0)) -> 1 | Q23: =IF(E23="","",--(MATCH(E23,$E$5:$E$560,0)=ROW()-4)) -> 1 | R23: =IF(Q23=1,COUNTIF($Q$5:Q23,1),"") -> 18
A24: T020 | B24: T017 | C24: 5 | D24: 密度 | E24: rho_chip | F24: ='01_入力仕様'!D27 -> 3210 | G24: kg/m³ | H24: =ABS(K24)*$F$5 -> 0.00081977092 | I24: 入力仕様 | J24: =1 -> 1 | K24: =K21*J24 -> 6.5908176e-05 | L24: =IF(K24>0,"増加→総重量増",IF(K24<0,"増加→総重量減","中立")) -> 増加→総重量増 | M24: 設計対象 | O24: =IF($A24="","",--(COUNTIF($B$5:$B$679,$A24)=0)) -> 1 | Q24: =IF(E24="","",--(MATCH(E24,$E$5:$E$560,0)=ROW()-4)) -> 1 | R24: =IF(Q24=1,COUNTIF($Q$5:Q24,1),"") -> 19
A25: T021 | B25: T004 | C25: 3 | D25: DBC重量 | E25: m_dbc | F25: =F26*F27*F28*0.000000001 -> 0.02696064 | G25: kg | H25: =ABS(K25)*$F$5 -> 0.16176384 | I25: m_dbc=A_dbc×t_dbc×rho_dbc×1E-9 | J25: =F25/F8 -> 0.15906989 | K25: =K8*J25 -> 0.013005535 | L25: =IF(K25>0,"増加→総重量増",IF(K25<0,"増加→総重量減","中立")) -> 増加→総重量増 | M25: 設計対象 | O25: =IF($A25="","",--(COUNTIF($B$5:$B$679,$A25)=0)) -> 0 | Q25: =IF(E25="","",--(MATCH(E25,$E$5:$E$560,0)=ROW()-4)) -> 1 | R25: =IF(Q25=1,COUNTIF($Q$5:Q25,1),"") -> 20
A26: T022 | B26: T021 | C26: 4 | D26: DBC面積 | E26: A_dbc | F26: =F218*F219*1000000 -> 4200 | G26: mm² | H26: =ABS(K26)*$F$5 -> 0.16176384 | I26: A_dbc=L_dbc×W_dbc×1E6 | J26: =1 -> 1 | K26: =K25*J26 -> 0.013005535 | L26: =IF(K26>0,"増加→総重量増",IF(K26<0,"増加→総重量減","中立")) -> 増加→総重量増 | M26: 設計対象 | O26: =IF($A26="","",--(COUNTIF($B$5:$B$679,$A26)=0)) -> 0 | Q26: =IF(E26="","",--(MATCH(E26,$E$5:$E$560,0)=ROW()-4)) -> 1 | R26: =IF(Q26=1,COUNTIF($Q$5:Q26,1),"") -> 21
A27: T023 | B27: T021 | C27: 4 | D27: DBC厚さ | E27: t_dbc | F27: =F220+F221+F222 -> 0.92 | G27: mm | H27: =ABS(K27)*$F$5 -> 0.16176384 | I27: t_dbc=t_cu_top+t_cer+t_cu_bot | J27: =1 -> 1 | K27: =K25*J27 -> 0.013005535 | L27: =IF(K27>0,"増加→総重量増",IF(K27<0,"増加→総重量減","中立")) -> 増加→総重量増 | M27: 設計対象 | O27: =IF($A27="","",--(COUNTIF($B$5:$B$679,$A27)=0)) -> 0 | Q27: =IF(E27="","",--(MATCH(E27,$E$5:$E$560,0)=ROW()-4)) -> 1 | R27: =IF(Q27=1,COUNTIF($Q$5:Q27,1),"") -> 22
A28: T024 | B28: T021 | C28: 4 | D28: DBC密度 | E28: rho_dbc | F28: =(F223*(F254+F256)+F224*F255)/F225 -> 6977.3913 | G28: kg/m³ | H28: =ABS(K28)*$F$5 -> 0.16176384 | I28: rho_dbc={rho_cu(t_top+t_bot)+rho_cer t_cer}/t_dbc | J28: =1 -> 1 | K28: =K25*J28 -> 0.013005535 | L28: =IF(K28>0,"増加→総重量増",IF(K28<0,"増加→総重量減","中立")) -> 増加→総重量増 | M28: 設計対象 | O28: =IF($A28="","",--(COUNTIF($B$5:$B$679,$A28)=0)) -> 0 | Q28: =IF(E28="","",--(MATCH(E28,$E$5:$E$560,0)=ROW()-4)) -> 1 | R28: =IF(Q28=1,COUNTIF($Q$5:Q28,1),"") -> 23
A29: T025 | B29: T004 | C29: 3 | D29: ベース重量 | E29: m_base | F29: =F30*F31*F32*0.000000001 -> 0.067392 | G29: kg | H29: =ABS(K29)*$F$5 -> 0.404352 | I29: m_base=A_base×t_base×rho_base×1E-9 | J29: =F29/F8 -> 0.39761809 | K29: =K8*J29 -> 0.032509207 | L29: =IF(K29>0,"増加→総重量増",IF(K29<0,"増加→総重量減","中立")) -> 増加→総重量増 | M29: 設計対象 | O29: =IF($A29="","",--(COUNTIF($B$5:$B$679,$A29)=0)) -> 0 | Q29: =IF(E29="","",--(MATCH(E29,$E$5:$E$560,0)=ROW()-4)) -> 1 | R29: =IF(Q29=1,COUNTIF($Q$5:Q29,1),"") -> 24
A30: T026 | B30: T025 | C30: 4 | D30: ベース面積 | E30: A_base | F30: =F229*F230*1000000 -> 5200 | G30: mm² | H30: =ABS(K30)*$F$5 -> 0.404352 | I30: A_base=L_base×W_base×1E6 | J30: =1 -> 1 | K30: =K29*J30 -> 0.032509207 | L30: =IF(K30>0,"増加→総重量増",IF(K30<0,"増加→総重量減","中立")) -> 増加→総重量増 | M30: 設計対象 | O30: =IF($A30="","",--(COUNTIF($B$5:$B$679,$A30)=0)) -> 0 | Q30: =IF(E30="","",--(MATCH(E30,$E$5:$E$560,0)=ROW()-4)) -> 1 | R30: =IF(Q30=1,COUNTIF($Q$5:Q30,1),"") -> 25
A31: T027 | B31: T025 | C31: 4 | D31: ベース厚さ | E31: t_base | F31: =MAX(F269,F231) -> 4.8 | G31: mm | H31: =ABS(K31)*$F$5 -> 0.404352 | I31: t_base=MAX(t_base_input,t_base_req) | J31: =1 -> 1 | K31: =K29*J31 -> 0.032509207 | L31: =IF(K31>0,"増加→総重量増",IF(K31<0,"増加→総重量減","中立")) -> 増加→総重量増 | M31: 設計対象 | O31: =IF($A31="","",--(COUNTIF($B$5:$B$679,$A31)=0)) -> 0 | Q31: =IF(E31="","",--(MATCH(E31,$E$5:$E$560,0)=ROW()-4)) -> 1 | R31: =IF(Q31=1,COUNTIF($Q$5:Q31,1),"") -> 26
A32: T028 | B32: T025 | C32: 4 | D32: ベース密度 | E32: rho_base | F32: ='01_入力仕様'!D40 -> 2700 | G32: kg/m³ | H32: =ABS(K32)*$F$5 -> 0.404352 | I32: 入力仕様 | J32: =1 -> 1 | K32: =K29*J32 -> 0.032509207 | L32: =IF(K32>0,"増加→総重量増",IF(K32<0,"増加→総重量減","中立")) -> 増加→総重量増 | M32: 設計対象 | O32: =IF($A32="","",--(COUNTIF($B$5:$B$679,$A32)=0)) -> 1 | Q32: =IF(E32="","",--(MATCH(E32,$E$5:$E$560,0)=ROW()-4)) -> 1 | R32: =IF(Q32=1,COUNTIF($Q$5:Q32,1),"") -> 27
A33: T029 | B33: T004 | C33: 3 | D33: 封止・端子重量 | E33: m_pkg | F33: ='01_入力仕様'!D41 -> 0.075 | G33: kg | H33: =ABS(K33)*$F$5 -> 0.45 | I33: 入力仕様 | J33: =F33/F8 -> 0.44250589 | K33: =K8*J33 -> 0.036179228 | L33: =IF(K33>0,"増加→総重量増",IF(K33<0,"増加→総重量減","中立")) -> 増加→総重量増 | M33: 設計対象 | O33: =IF($A33="","",--(COUNTIF($B$5:$B$679,$A33)=0)) -> 1 | Q33: =IF(E33="","",--(MATCH(E33,$E$5:$E$560,0)=ROW()-4)) -> 1 | R33: =IF(Q33=1,COUNTIF($Q$5:Q33,1),"") -> 28
A34: T030 | B34: T001 | C34: 1 | D34: 冷却系重量 | E34: M_cool | F34: =F35+F443+F457+F95+F540 -> 0.56688782 | G34: kg | H34: =ABS(K34)*$F$5 -> 0.56688782 | I34: M_cool=m_hx+m_cool_fix | J34: =F34/F5 -> 0.045576809 | K34: =K5*J34 -> 0.045576809 | L34: =IF(K34>0,"増加→総重量増",IF(K34<0,"増加→総重量減","中立")) -> 増加→総重量増 | M34: 設計対象 | O34: =IF($A34="","",--(COUNTIF($B$5:$B$679,$A34)=0)) -> 0 | Q34: =IF(E34="","",--(MATCH(E34,$E$5:$E$560,0)=ROW()-4)) -> 1 | R34: =IF(Q34=1,COUNTIF($Q$5:Q34,1),"") -> 29
A35: T031 | B35: T030 | C35: 2 | D35: 熱交換器重量 | E35: m_hx | F35: =F36/F82*F452*F459*F514*F536 -> 0.016887823 | G35: kg | H35: =ABS(K35)*$F$5 -> 0.016887823 | I35: m_hx=Q_req/q_cool×TIM×Tj×potting×package_cooling | J35: =F35/F34 -> 0.029790414 | K35: =K34*J35 -> 0.001357752 | L35: =IF(K35>0,"増加→総重量増",IF(K35<0,"増加→総重量減","中立")) -> 増加→総重量増 | M35: 設計対象 | O35: =IF($A35="","",--(COUNTIF($B$5:$B$679,$A35)=0)) -> 0 | Q35: =IF(E35="","",--(MATCH(E35,$E$5:$E$560,0)=ROW()-4)) -> 1 | R35: =IF(Q35=1,COUNTIF($Q$5:Q35,1),"") -> 30
A36: T032 | B36: T031 | C36: 3 | D36: 必要冷却能力 | E36: Q_req | F36: =F37*(F38+F444+F471+F479+F488+F504+F516+F534+F569+F595+F675) -> 777.77731 | G36: W | H36: =ABS(K36)*$F$5 -> 0.016887823 | I36: Q_req=K_th×(P_loss_semiconductor+P_bus+P_cap+P_filter+P_ctrl+P_DCDC+P_L_dc+P_damping) | J36: =1 -> 1 | K36: =K35*J36 -> 0.001357752 | L36: =IF(K36>0,"増加→総重量増",IF(K36<0,"増加→総重量減","中立")) -> 増加→総重量増 | M36: 設計対象 | N36: インバータ内部で除熱すべき損失のみを集計。HTS冷凍機の電気入力P_cryo_HTSは外部電源からのシステム電力ペナルティであり、インバータ内部発熱として二重加算しない。 | O36: =IF($A36="","",--(COUNTIF($B$5:$B$679,$A36)=0)) -> 0 | Q36: =IF(E36="","",--(MATCH(E36,$E$5:$E$560,0)=ROW()-4)) -> 1 | R36: =IF(Q36=1,COUNTIF($Q$5:Q36,1),"") -> 31
A37: T033 | B37: T032 | C37: 4 | D37: 熱設計マージン | E37: K_th | F37: ='01_入力仕様'!D51 -> 1.2 | G37: - | H37: =ABS(K37)*$F$5 -> 0.016887823 | I37: 入力仕様 | J37: =1 -> 1 | K37: =K36*J37 -> 0.001357752 | L37: =IF(K37>0,"増加→総重量増",IF(K37<0,"増加→総重量減","中立")) -> 増加→総重量増 | M37: 設計対象 | O37: =IF($A37="","",--(COUNTIF($B$5:$B$679,$A37)=0)) -> 1 | Q37: =IF(E37="","",--(MATCH(E37,$E$5:$E$560,0)=ROW()-4)) -> 1 | R37: =IF(Q37=1,COUNTIF($Q$5:Q37,1),"") -> 32
A38: T034 | B38: T032 | C38: 4 | D38: 半導体総損失 | E38: P_loss | F38: =F39+F68+F319+F332+F350+'01_入力仕様'!D334*'01_入力仕様'!D335*F660 -> 39.820745 | G38: W | H38: =ABS(K38)*$F$5 -> 0.00103755 | I38: P_loss=P_cond+P_sw+P_dead+P_gate+P_snub+BD-GaN substrate management loss | J38: =IFERROR(F38/(F38+F444+F471+F479+F488+F504+F516+F534+F569+F595+F675),0) -> 0.061437757 | K38: =K36*J38 -> 8.3417238e-05 | L38: =IF(K38>0,"増加→総重量増",IF(K38<0,"増加→総重量減","中立")) -> 増加→総重量増 | M38: 設計対象 | O38: =IF($A38="","",--(COUNTIF($B$5:$B$679,$A38)=0)) -> 0 | Q38: =IF(E38="","",--(MATCH(E38,$E$5:$E$560,0)=ROW()-4)) -> 1 | R38: =IF(Q38=1,COUNTIF($Q$5:Q38,1),"") -> 33
A39: T035 | B39: T034 | C39: 5 | D39: 導通損失 | E39: P_cond | F39: =IF(F649=1,F644*F646^2*F650,F644*F646^2*F44+F645*F646*F647) -> 10.599889 | G39: W | H39: =ABS(K39)*$F$5 -> 0.00027618556 | I39: P_cond=IF(BD-GaN CSI, N_sw_cond_eq×I_cond²×R_BD_GaN_eff, N_sw_cond_eq×I_cond²×R_on_eq+N_diode_cond_eq×I_cond×Vf) | J39: =IF(F38=0,0,F39/F38) -> 0.26619013 | K39: =K38*J39 -> 2.2204846e-05 | L39: =IF(K39>0,"増加→総重量増",IF(K39<0,"増加→総重量減","中立")) -> 増加→総重量増 | M39: 設計対象 | N39: 簡略一般モデル。2L:3SW、NPC:6SW+1.5diode、ANPC同期整流:6SW+0diode、CSI:2SW+2逆阻止diode。 | O39: =IF($A39="","",--(COUNTIF($B$5:$B$679,$A39)=0)) -> 0 | Q39: =IF(E39="","",--(MATCH(E39,$E$5:$E$560,0)=ROW()-4)) -> 1 | R39: =IF(Q39=1,COUNTIF($Q$5:Q39,1),"") -> 34
O40: =IF($A40="","",--(COUNTIF($B$5:$B$679,$A40)=0))
O41: =IF($A41="","",--(COUNTIF($B$5:$B$679,$A41)=0))
O42: =IF($A42="","",--(COUNTIF($B$5:$B$679,$A42)=0))
...

Sheet 03_ダッシュボード
A1: パワエレ・モータドライブ 感度解析ダッシュボード v3.2
A2: 集計元：02_ツリー A5:R679。主要感度集計を数式で自動更新。
A10: 変数 | B10: 正感度合計 S+ | C10: 負感度合計 S- | D10: ネット感度 S_net | E10: 最終変数判定 | F10: トレードオフ有無 | G10: Enable系
A11: =IFERROR(INDEX('02_ツリー'!$E$5:$E$679,MATCH(ROW()-10,'02_ツリー'!$R$5:$R$679,0)),"") -> M_inv | B11: =IF($A11="","",SUMIFS('02_ツリー'!$K$5:$K$679,'02_ツリー'!$E$5:$E$679,$A11,'02_ツリー'!$K$5:$K$679,">0")) -> 1 | C11: =IF($A11="","",SUMIFS('02_ツリー'!$K$5:$K$679,'02_ツリー'!$E$5:$E$679,$A11,'02_ツリー'!$K$5:$K$679,"<0")) -> 0 | D11: =IF($A11="","",B11+C11) -> 1 | E11: =IF($A11="","",--(COUNTIFS('02_ツリー'!$E$5:$E$679,$A11,'02_ツリー'!$O$5:$O$679,0)=0)) -> 0 | F11: =IF($A11="","",--AND(B11>0,C11<0)) -> 0 | G11: =IF($A11="","",--(LEFT(A11,7)="Enable_")) -> 0
A12: =IFERROR(INDEX('02_ツリー'!$E$5:$E$679,MATCH(ROW()-10,'02_ツリー'!$R$5:$R$679,0)),"") -> M_semi | B12: =IF($A12="","",SUMIFS('02_ツリー'!$K$5:$K$679,'02_ツリー'!$E$5:$E$679,$A12,'02_ツリー'!$K$5:$K$679,">0")) -> 0.1324108 | C12: =IF($A12="","",SUMIFS('02_ツリー'!$K$5:$K$679,'02_ツリー'!$E$5:$E$679,$A12,'02_ツリー'!$K$5:$K$679,"<0")) -> 0 | D12: =IF($A12="","",B12+C12) -> 0.1324108 | E12: =IF($A12="","",--(COUNTIFS('02_ツリー'!$E$5:$E$679,$A12,'02_ツリー'!$O$5:$O$679,0)=0)) -> 0 | F12: =IF($A12="","",--AND(B12>0,C12<0)) -> 0 | G12: =IF($A12="","",--(LEFT(A12,7)="Enable_")) -> 0
A13: =IFERROR(INDEX('02_ツリー'!$E$5:$E$679,MATCH(ROW()-10,'02_ツリー'!$R$5:$R$679,0)),"") -> N_power_device_total | B13: =IF($A13="","",SUMIFS('02_ツリー'!$K$5:$K$679,'02_ツリー'!$E$5:$E$679,$A13,'02_ツリー'!$K$5:$K$679,">0")) -> 0.1324108 | C13: =IF($A13="","",SUMIFS('02_ツリー'!$K$5:$K$679,'02_ツリー'!$E$5:$E$679,$A13,'02_ツリー'!$K$5:$K$679,"<0")) -> 0 | D13: =IF($A13="","",B13+C13) -> 0.1324108 | E13: =IF($A13="","",--(COUNTIFS('02_ツリー'!$E$5:$E$679,$A13,'02_ツリー'!$O$5:$O$679,0)=0)) -> 1 | F13: =IF($A13="","",--AND(B13>0,C13<0)) -> 0 | G13: =IF($A13="","",--(LEFT(A13,7)="Enable_")) -> 0
A14: =IFERROR(INDEX('02_ツリー'!$E$5:$E$679,MATCH(ROW()-10,'02_ツリー'!$R$5:$R$679,0)),"") -> m_mod | B14: =IF($A14="","",SUMIFS('02_ツリー'!$K$5:$K$679,'02_ツリー'!$E$5:$E$679,$A14,'02_ツリー'!$K$5:$K$679,">0")) -> 0.081759879 | C14: =IF($A14="","",SUMIFS('02_ツリー'!$K$5:$K$679,'02_ツリー'!$E$5:$E$679,$A14,'02_ツリー'!$K$5:$K$679,"<0")) -> 0 | D14: =IF($A14="","",B14+C14) -> 0.081759879 | E14: =IF($A14="","",--(COUNTIFS('02_ツリー'!$E$5:$E$679,$A14,'02_ツリー'!$O$5:$O$679,0)=0)) -> 0 | F14: =IF($A14="","",--AND(B14>0,C14<0)) -> 0 | G14: =IF($A14="","",--(LEFT(A14,7)="Enable_")) -> 0
A15: =IFERROR(INDEX('02_ツリー'!$E$5:$E$679,MATCH(ROW()-10,'02_ツリー'!$R$5:$R$679,0)),"") -> m_chip_mod | B15: =IF($A15="","",SUMIFS('02_ツリー'!$K$5:$K$679,'02_ツリー'!$E$5:$E$679,$A15,'02_ツリー'!$K$5:$K$679,">0")) -> 6.5908176e-05 | C15: =IF($A15="","",SUMIFS('02_ツリー'!$K$5:$K$679,'02_ツリー'!$E$5:$E$679,$A15,'02_ツリー'!$K$5:$K$679,"<0")) -> 0 | D15: =IF($A15="","",B15+C15) -> 6.5908176e-05 | E15: =IF($A15="","",--(COUNTIFS('02_ツリー'!$E$5:$E$679,$A15,'02_ツリー'!$O$5:$O$679,0)=0)) -> 0 | F15: =IF($A15="","",--AND(B15>0,C15<0)) -> 0 | G15: =IF($A15="","",--(LEFT(A15,7)="Enable_")) -> 0
A16: =IFERROR(INDEX('02_ツリー'!$E$5:$E$679,MATCH(ROW()-10,'02_ツリー'!$R$5:$R$679,0)),"") -> N_chip_mod | B16: =IF($A16="","",SUMIFS('02_ツリー'!$K$5:$K$679,'02_ツリー'!$E$5:$E$679,$A16,'02_ツリー'!$K$5:$K$679,">0")) -> 6.5908176e-05 | C16: =IF($A16="","",SUMIFS('02_ツリー'!$K$5:$K$679,'02_ツリー'!$E$5:$E$679,$A16,'02_ツリー'!$K$5:$K$679,"<0")) -> 0 | D16: =IF($A16="","",B16+C16) -> 6.5908176e-05 | E16: =IF($A16="","",--(COUNTIFS('02_ツリー'!$E$5:$E$679,$A16,'02_ツリー'!$O$5:$O$679,0)=0)) -> 0 | F16: =IF($A16="","",--AND(B16>0,C16<0)) -> 0 | G16: =IF($A16="","",--(LEFT(A16,7)="Enable_")) -> 0
A17: =IFERROR(INDEX('02_ツリー'!$E$5:$E$679,MATCH(ROW()-10,'02_ツリー'!$R$5:$R$679,0)),"") -> k_chip | B17: =IF($A17="","",SUMIFS('02_ツリー'!$K$5:$K$679,'02_ツリー'!$E$5:$E$679,$A17,'02_ツリー'!$K$5:$K$679,">0")) -> 6.5908176e-05 | C17: =IF($A17="","",SUMIFS('02_ツリー'!$K$5:$K$679,'02_ツリー'!$E$5:$E$679,$A17,'02_ツリー'!$K$5:$K$679,"<0")) -> 0 | D17: =IF($A17="","",B17+C17) -> 6.5908176e-05 | E17: =IF($A17="","",--(COUNTIFS('02_ツリー'!$E$5:$E$679,$A17,'02_ツリー'!$O$5:$O$679,0)=0)) -> 1 | F17: =IF($A17="","",--AND(B17>0,C17<0)) -> 0 | G17: =IF($A17="","",--(LEFT(A17,7)="Enable_")) -> 0
A18: =IFERROR(INDEX('02_ツリー'!$E$5:$E$679,MATCH(ROW()-10,'02_ツリー'!$R$5:$R$679,0)),"") -> I_phase | B18: =IF($A18="","",SUMIFS('02_ツリー'!$K$5:$K$679,'02_ツリー'!$E$5:$E$679,$A18,'02_ツリー'!$K$5:$K$679,">0")) -> 0.047694862 | C18: =IF($A18="","",SUMIFS('02_ツリー'!$K$5:$K$679,'02_ツリー'!$E$5:$E$679,$A18,'02_ツリー'!$K$5:$K$679,"<0")) -> -0.018791044 | D18: =IF($A18="","",B18+C18) -> 0.028903818 | E18: =IF($A18="","",--(COUNTIFS('02_ツリー'!$E$5:$E$679,$A18,'02_ツリー'!$O$5:$O$679,0)=0)) -> 0 | F18: =IF($A18="","",--AND(B18>0,C18<0)) -> 1 | G18: =IF($A18="","",--(LEFT(A18,7)="Enable_")) -> 0
A19: =IFERROR(INDEX('02_ツリー'!$E$5:$E$679,MATCH(ROW()-10,'02_ツリー'!$R$5:$R$679,0)),"") -> V_ll | B19: =IF($A19="","",SUMIFS('02_ツリー'!$K$5:$K$679,'02_ツリー'!$E$5:$E$679,$A19,'02_ツリー'!$K$5:$K$679,">0")) -> 0.018789803 | C19: =IF($A19="","",SUMIFS('02_ツリー'!$K$5:$K$679,'02_ツリー'!$E$5:$E$679,$A19,'02_ツリー'!$K$5:$K$679,"<0")) -> -0.047666743 | D19: =IF($A19="","",B19+C19) -> -0.02887694 | E19: =IF($A19="","",--(COUNTIFS('02_ツリー'!$E$5:$E$679,$A19,'02_ツリー'!$O$5:$O$679,0)=0)) -> 1 | F19: =IF($A19="","",--AND(B19>0,C19<0)) -> 1 | G19: =IF($A19="","",--(LEFT(A19,7)="Enable_")) -> 0
A20: =IFERROR(INDEX('02_ツリー'!$E$5:$E$679,MATCH(ROW()-10,'02_ツリー'!$R$5:$R$679,0)),"") -> PF | B20: =IF($A20="","",SUMIFS('02_ツリー'!$K$5:$K$679,'02_ツリー'!$E$5:$E$679,$A20,'02_ツリー'!$K$5:$K$679,">0")) -> 0.018789803 | C20: =IF($A20="","",SUMIFS('02_ツリー'!$K$5:$K$679,'02_ツリー'!$E$5:$E$679,$A20,'02_ツリー'!$K$5:$K$679,"<0")) -> -0.047666743 | D20: =IF($A20="","",B20+C20) -> -0.02887694 | E20: =IF($A20="","",--(COUNTIFS('02_ツリー'!$E$5:$E$679,$A20,'02_ツリー'!$O$5:$O$679,0)=0)) -> 1 | F20: =IF($A20="","",--AND(B20>0,C20<0)) -> 1 | G20: =IF($A20="","",--(LEFT(A20,7)="Enable_")) -> 0
A21: =IFERROR(INDEX('02_ツリー'!$E$5:$E$679,MATCH(ROW()-10,'02_ツリー'!$R$5:$R$679,0)),"") -> eta | B21: =IF($A21="","",SUMIFS('02_ツリー'!$K$5:$K$679,'02_ツリー'!$E$5:$E$679,$A21,'02_ツリー'!$K$5:$K$679,">0")) -> 0.018789803 | C21: =IF($A21="","",SUMIFS('02_ツリー'!$K$5:$K$679,'02_ツリー'!$E$5:$E$679,$A21,'02_ツリー'!$K$5:$K$679,"<0")) -> -0.1133911 | D21: =IF($A21="","",B21+C21) -> -0.094601295 | E21: =IF($A21="","",--(COUNTIFS('02_ツリー'!$E$5:$E$679,$A21,'02_ツリー'!$O$5:$O$679,0)=0)) -> 1 | F21: =IF($A21="","",--AND(B21>0,C21<0)) -> 1 | G21: =IF($A21="","",--(LEFT(A21,7)="Enable_")) -> 0
A22: =IFERROR(INDEX('02_ツリー'!$E$5:$E$679,MATCH(ROW()-10,'02_ツリー'!$R$5:$R$679,0)),"") -> I_chip | B22: =IF($A22="","",SUMIFS('02_ツリー'!$K$5:$K$679,'02_ツリー'!$E$5:$E$679,$A22,'02_ツリー'!$K$5:$K$679,">0")) -> 0 | C22: =IF($A22="","",SUMIFS('02_ツリー'!$K$5:$K$679,'02_ツリー'!$E$5:$E$679,$A22,'02_ツリー'!$K$5:$K$679,"<0")) -> -6.5908176e-05 | D22: =IF($A22="","",B22+C22) -> -6.5908176e-05 | E22: =IF($A22="","",--(COUNTIFS('02_ツリー'!$E$5:$E$679,$A22,'02_ツリー'!$O$5:$O$679,0)=0)) -> 0 | F22: =IF($A22="","",--AND(B22>0,C22<0)) -> 0 | G22: =IF($A22="","",--(LEFT(A22,7)="Enable_")) -> 0
... A504: =IFERROR(INDEX('02_ツリー'!$E$5:$E$679,MATCH(ROW()-10,'02_ツリー'!$R$5:$R$679,0)),"") | B504: =IF($A504="","",SUMIFS('02_ツリー'!$K$5:$K$679,'02_ツリー'!$E$5:$E$679,$A504,'02_ツリー'!$K$5:$K$679,">0")) | C504: =IF($A504="","",SUMIFS('02_ツリー'!$K$5:$K$679,'02_ツリー'!$E$5:$E$679,$A504,'02_ツリー'!$K$5:$K$679,"<0")) | D504: =IF($A504="","",B504+C504) | E504: =IF($A504="","",--(COUNTIFS('02_ツリー'!$E$5:$E$679,$A504,'02_ツリー'!$O$5:$O$679,0)=0)) | F504: =IF($A504="","",--AND(B504>0,C504<0)) | G504: =IF($A504="","",--(LEFT(A504,7)="Enable_"))

Sheet 07_システム要求
A1: システム要求・自動推奨設計値
A4: 入力自動化方針：システム要求から一意またはほぼ一意に決まる値は自動適用可能とし、損失・重量の最適化対象となる設計変数は推奨値のみ提示して固定しない。「自動適用」は初期設計を簡略化するための設計ルールであり、最終設計値ではない。
A8: 区分 | B8: システム要求 / 設計ルール | C8: 変数 | D8: 入力値 | E8: 単位 | F8: 自動/手動 | G8: 使用先 | H8: 備考・計算詳細 | J8: 推奨ID | K8: 推奨設計値 | L8: 変数 | M8: 推奨値 | N8: 単位 | O8: 適用方針 | P8: 計算式/設計ルール | Q8: 注意
A9: 電力 | B9: 定格出力 | C9: SYS_Pout | D9: 100 | E9: kW | F9: 要求 | G9: P_out | H9: 上位アプリケーションで固定 | J9: R001 | K9: モータ電気周波数 | L9: f_e | M9: =D10*D11/60 -> 800 | N9: Hz | O9: 自動計算 | P9: n_max×pole_pairs/60 | Q9: システム要求から一意
A10: モータ | B10: 最高機械回転数 | C10: SYS_nmax | D10: 12000 | E10: rpm | F10: 要求 | G10: f_e,f_sw | H10: 最高運転点 | J10: R002 | K10: 初期スイッチング周波数 | L10: f_sw | M10: =MAX(M9*D16,IF(D17=1,20000,0),M22,M23) -> 16000 | N10: Hz | O10: 自動適用候補 | P10: MAX(f_e×PWM回数, 可聴域下限, リップル要求由来fsw, 制御帯域由来fsw) | Q10: 回転数だけでなく電流リップル要求・電流制御帯域も反映
A11: モータ | B11: 極対数 | C11: SYS_pole_pairs | D11: 4 | E11: - | F11: 要求 | G11: f_e,f_sw | H11: 電気周波数=f_mech×極対数 | J11: R003 | K11: 相電流RMS | L11: I_phase_req | M11: =D9*1000/(SQRT(3)*D12*D14*D15) -> 156.63328 | N11: A | O11: 自動計算 | P11: Pout/(sqrt(3)×Vll×PF×eta) | Q11: Pout固定要求
A12: モータ | B12: 最大線間電圧RMS | C12: SYS_Vll | D12: 400 | E12: V | F12: 要求/協調設計 | G12: V_ll,I_phase | H12: モータ巻線・逆起電圧設計と協調 | J12: R004 | K12: DC入力電流 | L12: I_dc_req | M12: =D9*1000/(D13*D15) -> 128.86598 | N12: A | O12: 自動計算 | P12: Pout/(Vdc×eta) | Q12: Pout固定要求
A13: 電源 | B13: DCバス公称電圧 | C13: SYS_Vdc | D13: 800 | E13: V | F13: 要求 | G13: V_dc,耐圧 | H13: バッテリ/電源システムから決定 | J13: R005 | K13: 半導体必要耐圧 | L13: V_block_req_rec | M13: =IF(AND('01_入力仕様'!D296=0,OR(D25="3L-NPC",D25="3L-ANPC")),0.5*D13+'02_ツリー'!F347,D13+'02_ツリー'!F347) -> 884.58197 | N13: V | O13: 自動計算 | P13: CSI=1: Vdc+surge、3L-NPC/ANPC: Vdc/2+surge、2L-VSI: Vdc+surge | Q13: モデル上の1素子当たり必要阻止電圧
A14: 性能 | B14: 目標力率 | C14: SYS_PF | D14: 0.95 | E14: - | F14: 要求 | G14: PF,I_phase | H14: モータ制御条件 | J14: R006 | K14: 半導体標準耐圧クラス | L14: V_device_class_rec | M14: =IF(M13<=650,650,IF(M13<=1200,1200,IF(M13<=1700,1700,3300))) -> 1200 | N14: V | O14: 推奨のみ | P14: V_block_req_recを650/1200/1700/3300Vへ切上げ | Q14: 部品選定用推奨値。物理耐圧計算とは分離
A15: 性能 | B15: 目標変換効率 | C15: SYS_eta | D15: 0.97 | E15: - | F15: 要求 | G15: eta,I_phase | H15: 初期見積用 | J15: R007 | K15: チップ面積初期推奨 | L15: A_chip_rec | M15: ='01_入力仕様'!D25*(M11/'02_ツリー'!F12)*(M14/1200)^0.6 -> 100 | N15: mm2 | O15: 推奨のみ | P15: 現行A_chip×I_phase/I_phase_baseline×(Vclass/1200)^0.6 | Q15: 現製品基準のスケーリング。最適化変数なので自動固定しない
A16: 制御 | B16: 最低PWM回数/電気周期 | C16: SYS_pwm_ratio | D16: 20 | E16: - | F16: 設計ルール | G16: f_sw | H16: 初期値。電流リップル/制御帯域/損失で再調整 | J16: R008 | K16: 並列数初期推奨 | L16: N_parallel_rec | M16: =MAX(1,CEILING(D26*M11/('01_入力仕様'!D33*'01_入力仕様'!D34*'01_入力仕様'!D25),1)) -> 3 | N16: - | O16: 推奨のみ | P16: MAX(1,CEILING(overload×I_phase/(J_chip×k_active×A_chip))) | Q16: 離散値。感度解析対象なので自動固定しない
A17: 制御 | B17: 可聴域回避を優先 | C17: SYS_audible_avoid | D17: 0 | E17: 0/1 | F17: 要求 | G17: f_sw | H17: 1の場合は20kHzを初期下限とする簡易ルール | J17: R009 | K17: デッドタイム初期推奨 | L17: t_dead_rec | M17: =1.5*MAX('01_入力仕様'!D153*'01_入力仕様'!D150/'01_入力仕様'!D152,'01_入力仕様'!D154*'01_入力仕様'!D151/'01_入力仕様'!D152) -> 7.5e-08 | N17: s | O17: 推奨のみ | P17: 1.5×MAX(t_on,t_off) | Q17: デバイス/ゲート条件で再調整
A18: 熱 | B18: 最大周囲温度 | C18: SYS_Tamb | D18: 45 | E18: degC | F18: 要求 | G18: T_amb,冷却 | H18: 設置環境 | J18: R010 | K18: ゲートドライバ数 | L18: N_gate_rec | M18: =IF('01_入力仕様'!D296=1,IF('01_入力仕様'!D334=1,6*'01_入力仕様'!D344,6),IF(D25="2L-VSI",6,IF(D25="3L-NPC",12,IF(D25="3L-ANPC",18,6)))) -> 6 | N18: 個 | O18: 自動適用 | P18: CSI=6、2L=6、3L-NPC=12、3L-ANPC=18 | Q18: 制御スイッチ数と一致。ダイオードにはゲートドライバを付けない。
A19: 熱 | B19: 冷媒入口温度 | C19: SYS_Tcool | D19: 65 | E19: degC | F19: 要求 | G19: T_cool_ref | H19: 液冷/空冷境界条件 | J19: R011 | K19: 要求DCリンク容量 | L19: C_req_rec | M19: ='02_ツリー'!F98 -> 1.6521279 | N19: mF | O19: 自動計算 | P19: 現行C_req式を参照 | Q19: 容量/リップル/寿命の最大要求で最終決定
A20: 熱 | B20: 目標接合温度 | C20: SYS_Tj | D20: 150 | E20: degC | F20: 設計要求 | G20: Tj_target | H20: 信頼性と冷却重量のトレードオフ | J20: R012 | K20: バスバー必要断面積 | L20: A_bus_rec | M20: ='02_ツリー'!F115 -> 32.216495 | N20: mm2 | O20: 自動計算 | P20: Idc/J_bus | Q20: 熱条件で再計算
A21: 信頼性 | B21: 要求寿命 | C21: SYS_life | D21: 150000 | E21: h | F21: 要求 | G21: life_cap_req | H21: コンデンサ寿命等へ展開 | J21: R013 | K21: オン抵抗初期推奨 | L21: R_on_target_rec | M21: ='02_ツリー'!F44*('01_入力仕様'!D25/M15)*(M14/MAX(M13,1))^2.2 -> 0.00028170006 | N21: ohm | O21: 推奨のみ | P21: 現行モデルRon×(現A_chip/A_chip_rec)×(標準耐圧/必要耐圧)^2.2 | Q21: 現製品基準の簡易スケーリング。A_chip/Ronは探索変数なので自動固定しない
A22: 配線 | B22: モータケーブル長 | C22: SYS_cable_len | D22: 2 | E22: m | F22: 要求 | G22: dv/dt,CM | H22: 長いほど反射・CM対策重要 | J22: R014 | K22: リップル要求由来fsw | L22: f_sw_ripple | M22: ='01_入力仕様'!D289*D13/(D24*D23*SQRT(2)*M11) -> 12898.313 | N22: Hz | O22: 自動計算 | P22: k_ripple_voltage×Vdc/(Lmotor×ripple_i×Ipk) | Q22: 簡易電流リップル上限制約
A23: 制御 | B23: 許容相電流リップル率 | C23: SYS_ripple_i | D23: 0.1 | E23: - | F23: 要求 | G23: f_sw/フィルタ | H23: モータLと合わせてfsw妥当性評価 | J23: R015 | K23: 制御帯域由来fsw | L23: f_sw_bw | M23: ='01_入力仕様'!D290*D30 -> 10000 | N23: Hz | O23: 自動計算 | P23: k_fsw_bw×BW_current | Q23: 制御帯域に対する最低キャリア倍率
A24: モータ | B24: 相インダクタンス | C24: SYS_Lmotor | D24: 0.00035 | E24: H | F24: 要求/既知値 | G24: f_sw/電流リップル | H24: モータ設計値 | J24: R016 | K24: パワーデバイス総数 | L24: N_power_device_total_rec | M24: =IF('01_入力仕様'!D296=1,IF('01_入力仕様'!D334=1,6,12),IF(D25="2L-VSI",6,IF(D25="3L-NPC",18,IF(D25="3L-ANPC",18,6)))) -> 6 | N24: 個 | O24: 自動適用 | P24: CSI=12、2L=6、3L-NPC=18、3L-ANPC=18 | Q24: CSI=6SW+6逆阻止diode。NPC=12SW+6 clamp diode。ANPC=18SW。
A25: 回路 | B25: 主回路トポロジー | C25: SYS_topology | D25: 2L-VSI | E25: - | F25: 設計選択 | G25: VSI素子数/耐圧 | H25: VSI方式のみ選択。2L-VSI / 3L-NPC / 3L-ANPC。CSIは10_シナリオ入力のEnable_CSIで別系統として選択。 | J25: R017 | K25: 追加ダイオード数 | L25: N_diode_extra_rec | M25: =IF('01_入力仕様'!D296=1,IF('01_入力仕様'!D334=1,0,6),IF(D25="3L-NPC",6,0)) -> 0 | N25: 個 | O25: 自動適用 | P25: CSI=6、NPC=6、2L/ANPC=0 | Q25: CSI逆阻止/NPCクランプ用追加ダイオード。
A26: 保護 | B26: 短時間過負荷倍率 | C26: SYS_overload | D26: 1.5 | E26: pu | F26: 要求 | G26: 半導体電流余裕 | H26: 短絡保護/並列数の初期推奨
A27: 絶縁 | B27: 要求最大dv/dt | C27: SYS_dvdt_max | D27: 10 | E27: kV/us | F27: 要求 | G27: gate/filter | H27: モータ絶縁・ケーブル条件から設定
A28: 安全 | B28: DCリンク放電要求時間 | C28: SYS_discharge_time | D28: 5 | E28: s | F28: 要求 | G28: 放電回路 | H28: Vdcから安全電圧までの要求時間
A29: 安全 | B29: 放電完了安全電圧 | C29: SYS_safe_voltage | D29: 60 | E29: V | F29: 要求 | G29: 放電回路 | H29: サービス/安全要求の簡易設定
A30: 制御 | B30: 電流制御帯域 | C30: SYS_BW_current | D30: 1000 | E30: Hz | F30: 要求 | G30: f_sw | H30: fswは制御帯域の十分上に設定

Sheet 09_基準仕様
A1: 09_基準仕様：材料・技術世代・製品基準値
A4: 同じ材料・同じ技術世代でシナリオ比較する限り固定する値です。毎回の比較では編集しません。材料や技術世代を変える場合だけ変更してください。
A8: No. | B8: 分類 | C8: 仕様 / 技術パラメータ | D8: 変数 | E8: 基準値 | F8: 単位 | G8: 旧入力区分 | H8: 主な影響先 | I8: 備考
A9: 1 | B9: 製品仕様 | C9: 許容DC電圧リップル率 | D9: r_vdc | E9: 0.05 | F9: - | G9: 設計変数 | H9: C_req | I9: DCリンク電圧リップル許容値5%を基準設計値として採用。物理定数ではなくC_reqを決めるシステム設計要求。実機のDCバス品質要求に合わせて変更する。
A10: 2 | B10: 製品仕様 | C10: DCリンクバッファ時間 | D10: t_buf | E10: 0.0005 | F10: s | G10: 設計変数 | H10: C_req | I10: DCリンクCのエネルギーバッファ時間0.5 msを基準設計値として採用。物理定数ではなくC_reqを決める簡略設計仮定。負荷過渡/制御帯域の要求で校正する。
A11: 3 | B11: 半導体 | C11: パワーデバイス個数（旧基準値） | D11: N_power_device | E11: 6 | F11: 個 | G11: 旧基準値 | H11: M_semi/P_sw | I11: 実使用値はSYS_topologyおよびEnable_CSIから自動算出。
A12: 4 | B12: 半導体 | C12: DC電圧→必要耐圧係数 | D12: K_vblk | E12: 1 | F12: - | G12: 技術係数 | H12: V_block_req | I12: 2L-VSI/CSIでは V_block_req=K_vblk×Vdc+surge。3L-NPC/ANPCでは1素子当たり Vdc/2+surge とし、K_vblkは3L枝には適用しない。surgeは直流印加電圧が半分でも発生するため加算する。
A13: 5 | B13: 半導体 | C13: ドリフト層電界利用率 | D13: k_Euse | E13: 0.72 | F13: - | G13: 技術係数 | H13: E_allow | I13: 材料臨界電界E_critをそのまま使わず72%に制限する設計利用率。欠陥・温度・電界集中・信頼性余裕をまとめた簡略係数で、普遍定数ではない。
A14: 6 | B14: 半導体 | C14: 材料臨界電界 | D14: E_crit | E14: 250000000 | F14: V/m | G14: 材料 | H14: E_allow | I14: 4H-SiCの臨界電界の代表値として2.5 MV/cm (=2.5×10^8 V/m)を採用。結晶方位・ドーピング・温度で変化するため、設計余裕は別変数k_Euseで与える。参考: https://repository.kulib.kyoto-u.ac.jp/dspace/bitstream/2433/288729/1/dkogk05254.pdf
A15: 7 | B15: 半導体 | C15: ドリフト層厚余裕係数 | D15: K_tdrift | E15: 1.15 | F15: - | G15: 技術係数 | H15: t_drift | I15: 理想ドリフト層厚に15%余裕を持たせる簡略安全係数。端部電界・製造ばらつき等をまとめた設計仮定で、デバイス実測/TCADで校正する。
A16: 8 | B16: 半導体 | C16: 基準ドーピング濃度 | D16: N_d_ref | E16: 8e+21 | F16: 1/m³ | G16: 材料 | H16: N_drift | I16: 説明用
A17: 9 | B17: 半導体 | C17: 耐圧基準 | D17: V_ref_nd | E17: 1200 | F17: V | G17: 技術係数 | H17: N_drift | I17: ドリフト層ドーピングの正規化基準として1200 Vを採用。物理定数ではなく比率式の基準点。1200 V級SiCデバイスを基準にしたモデル正規化値。
A18: 10 | B18: 半導体 | C18: ドーピング耐圧指数 | D18: a_nd | E18: 1.2 | F18: - | G18: 技術係数 | H18: N_drift | I18: N∝V^-a
A19: 11 | B19: 半導体 | C19: 電子移動度 | D19: mu_n | E19: 0.08 | F19: m²/(V·s) | G19: 材料 | H19: rho_drift | I19: 説明用SiC
A20: 12 | B20: 半導体 | C20: 素電荷 | D20: q_e | E20: 1.602e-19 | F20: C | G20: 固定定数 | H20: rho_drift | I20: 物理定数
... A116: 108 | B116: バスバー熱 | C116: 銅抵抗率 | D116: rho_e_bus | E116: 1.72e-08 | F116: Ωm | G116: 材料 | H116: J_bus_phys | I116: 銅(Cu)の20°C近傍の抵抗率として1.72E-8 Ωmを採用。温度上昇による抵抗率変化は別係数側で扱う。
A117: 109 | B117: バスバー熱 | C117: 表面積/体積係数 | D117: k_sav_bus | E117: =2*(1/'01_入力仕様'!D227+'01_入力仕様'!D227/((((('01_入力仕様'!D5*1000)/('01_入力仕様'!D6*'01_入力仕様'!D9))/'01_入力仕様'!D58)*0.000001))) -> 1426.4533 | F117: 1/m | G117: 技術係数 | H117: J_bus_phys | I117: 基準断面積A_ref=I_dc/J_bus_refとt_bus_condから長方形導体S/V=2(1/t+t/A_ref)を自動算出。一般的な幾何式。
A118: 110 | B118: EMI磁性 | C118: コア許容磁束密度 | D118: B_max | E118: 0.25 | F118: T | G118: 材料 | H118: u_core | I118: 高周波磁性部品の設計磁束密度0.25 T。MnZnフェライト等の高周波設計で飽和・損失余裕を持たせる代表的設計値で、採用コア材のB-H/損失データで校正する。
A119: 111 | B119: EMI磁性 | C119: コア透磁率係数 | D119: k_mu_core | E119: 1 | F119: - | G119: 材料 | H119: u_core | I119: コア透磁率影響の正規化係数。1.0は基準コア特性をそのまま使う意味で、実透磁率そのものではない。実コアの周波数・温度依存μe/B-H特性または磁気FEMで校正する。
A120: 112 | B120: EMI磁性 | C120: 巻線充填率 | D120: k_fill_L | E120: 0.4 | F120: - | G120: 技術係数 | H120: k_mL_phys | I120: 巻線窓の銅充填率40%を基準設計値として採用。絶縁・ボビン・巻線余裕を含む一般的な一次設計仮定で、実巻線設計で校正する。
A121: 113 | B121: EMI磁性 | C121: コア/銅等価密度 | D121: rho_L_eq | E121: 5000 | F121: kg/m³ | G121: 材料 | H121: k_mL_phys | I121: 磁性コアとCu巻線を一体化した等価密度5,000 kg/m³。Cuとフェライトの混合体としての重量換算用簡略値。実BOMで校正する。
A122: 114 | B122: 制御回路 | C122: 制御PCB面積 | D122: A_ctrl_pcb | E122: 0.03 | F122: m² | G122: 設計変数 | H122: m_ctrl_pcb | I122: 100 kW級基準モデルの制御PCB面積として置いた初期設計値。物理定数ではない。m_ctrl_pcbの一次見積り用で、実機BOM・CAD・採用部品データに置換/校正する。
A123: 115 | B123: 制御回路 | C123: 制御PCB厚さ | D123: t_ctrl_pcb | E123: 0.0016 | F123: m | G123: 設計変数 | H123: m_ctrl_pcb | I123: 100 kW級基準モデルの制御PCB厚さとして置いた初期設計値。物理定数ではない。m_ctrl_pcbの一次見積り用で、実機BOM・CAD・採用部品データに置換/校正する。
A124: 116 | B124: 制御回路 | C124: PCB等価密度 | D124: rho_ctrl_pcb | E124: 1900 | F124: kg/m³ | G124: 材料 | H124: m_ctrl_pcb | I124: FR-4/銅箔を含むPCB基板の等価密度1,900 kg/m³を重量換算に採用。搭載部品重量は別項m_ctrl_compで扱う。
A125: 117 | B125: 制御回路 | C125: PCB搭載部品重量 | D125: m_ctrl_comp | E125: 0.1 | F125: kg | G125: 設計変数 | H125: m_ctrl_pcb | I125: 100 kW級基準モデルのPCB搭載部品重量として置いた初期設計値。物理定数ではない。m_ctrl_pcbの一次見積り用で、実機BOM・CAD・採用部品データに置換/校正する。
A126: 118 | B126: ゲート回路 | C126: ドライバ単体重量 | D126: m_gate_unit | E126: 0.018 | F126: kg/個 | G126: 設計変数 | H126: m_gate | I126: 100 kW級基準モデルのドライバ単体重量として置いた初期設計値。物理定数ではない。m_gateの一次見積り用で、実機BOM・CAD・採用部品データに置換/校正する。
A127: 119 | B127: 制御回路 | C127: 補助電源重量 | D127: m_aux_supply | E127: 0.12 | F127: kg | G127: 設計変数 | H127: M_ctrl | I127: 100 kW級基準モデルの補助電源重量として置いた初期設計値。物理定数ではない。M_ctrlの一次見積り用で、実機BOM・CAD・採用部品データに置換/校正する。
A128: 120 | B128: センサ | C128: 電流センサ数 | D128: N_isens | E128: 3 | F128: 個 | G128: 設計変数 | H128: m_isens | I128: 100 kW級基準モデルの電流センサ数として置いた初期設計値。物理定数ではない。m_isensの一次見積り用で、実機BOM・CAD・採用部品データに置換/校正する。
A129: 121 | B129: センサ | C129: 電流センサ単体重量 | D129: m_isens_unit | E129: 0.045 | F129: kg/個 | G129: 設計変数 | H129: m_isens | I129: 100 kW級基準モデルの電流センサ単体重量として置いた初期設計値。物理定数ではない。m_isensの一次見積り用で、実機BOM・CAD・採用部品データに置換/校正する。
... A209: 201 | B209: バスバー | C209: 導体厚さ | D209: t_bus_cond | E209: 0.0015 | F209: m | G209: 設計変数 | H209: k_ac_bus | I209: バスバー導体厚1.5 mmを基準構造値として採用。電流密度・skin effect・製造性から最適化する。
A210: 202 | B210: バスバー | C210: 基準表皮深さ | D210: delta_skin_ref | E210: =SQRT($E$116/(PI()*'01_入力仕様'!D10*4*PI()*0.0000001)) -> 0.00052182438 | F210: m | G210: 技術係数 | H210: k_ac_bus | I210: 固定値ではなく銅の表皮深さを自動計算。δ=SQRT(ρ/(πfμ0))、μr≈1。fはスイッチング周波数。16 kHz・ρ=1.72E-8 Ωmでは約0.522 mm。 Formula reference: https://www.allaboutcircuits.com/tools/skin-depth-calculator
A211: 203 | B211: バスバー | C211: 積層追加重量 | D211: m_laminate_unit | E211: 0.035 | F211: kg/層 | G211: 技術係数 | H211: M_laminate | I211: M_laminateの簡略式で用いる積層追加重量の補正/正規化係数。普遍定数ではなく基準モデル再現用の経験値・設計仮定。実測/詳細解析/部品データで校正する。
A212: 204 | B212: dvdtフィルタ | C212: dv/dtフィルタ追加重量 | D212: m_dvdt_filter | E212: 0.18 | F212: kg | G212: 技術係数 | H212: M_inv | I212: M_invの簡略式で用いるdv/dtフィルタ追加重量の補正/正規化係数。普遍定数ではなく基準モデル再現用の経験値・設計仮定。実測/詳細解析/部品データで校正する。
A213: 205 | B213: dvdtフィルタ | C213: EMI低減率 | D213: k_dvdt_reduce | E213: 0.75 | F213: - | G213: 技術係数 | H213: M_slew_emi | I213: M_slew_emiの簡略式で用いるEMI低減率の補正/正規化係数。普遍定数ではなく基準モデル再現用の経験値・設計仮定。実測/詳細解析/部品データで校正する。
A214: 206 | B214: dvdtフィルタ | C214: 出力フィルタ損失 | D214: P_dvdt_filter_on | E214: 120 | F214: W | G214: 技術係数 | H214: Q_req | I214: Q_reqの簡略式で用いる出力フィルタ損失の補正/正規化係数。普遍定数ではなく基準モデル再現用の経験値・設計仮定。実測/詳細解析/部品データで校正する。
A215: 207 | B215: CMフィルタ | C215: アクティブCMフィルタ基準重量 | D215: m_CM_active_ref | E215: 0.08 | F215: kg | G215: 技術係数 | H215: M_CM_active | I215: 基準CM要求比におけるアクティブCMキャンセル回路の等価重量0.08 kgを校正点として採用。一般値ではない。実回路のセンサ、アンプ/スイッチ、磁気、PCB、冷却/取付のBOM重量へ置換する。
A216: 208 | B216: CMフィルタ | C216: アクティブ併用時パッシブ重量低減率 | D216: k_CM_active_passive_reduce | E216: 0.65 | F216: - | G216: 技術係数 | H216: M_CM_passive | I216: Hybrid時にアクティブCMキャンセルが担う減衰分だけパッシブLC重量を低減する簡略係数。
A217: 209 | B217: CMフィルタ | C217: アクティブCM重量指数 | D217: a_CM_active_mass | E217: 0.3 | F217: - | G217: 技術係数 | H217: M_CM_active | I217: CM要求比に対するアクティブCM回路重量のスケーリング指数0.3は感度解析用の経験係数。一般式ではない。複数要求点の回路設計/BOMからM∝k_CM_req^aをフィッティングして校正する。
A218: 210 | B218: EMI/構造 | C218: シールド追加重量 | D218: m_shield | E218: 0.12 | F218: kg | G218: 技術係数 | H218: M_shield | I218: M_shieldの簡略式で用いるシールド追加重量の補正/正規化係数。普遍定数ではなく基準モデル再現用の経験値・設計仮定。実測/詳細解析/部品データで校正する。
A219: 211 | B219: EMI/構造 | C219: シールドEMI低減率 | D219: k_shield_reduce | E219: 0.35 | F219: - | G219: 技術係数 | H219: M_emi | I219: M_emiの簡略式で用いるシールドEMI低減率の補正/正規化係数。普遍定数ではなく基準モデル再現用の経験値・設計仮定。実測/詳細解析/部品データで校正する。
...

Sheet 10_シナリオ入力
A1: 10_シナリオ入力：毎回の設計選択を27項目に集約
A4: システム要求とは別に、シナリオごとに設計者が明示的に選択する項目だけを集約しています。01_入力仕様はこの値を自動参照します。
A8: No. | B8: 分類 | C8: 仕様 / 技術パラメータ | D8: 変数 | E8: シナリオ値 | F8: 単位 | G8: 主な影響先 | H8: 備考
A9: 1 | B9: ソフトスイッチング | C9: ソフトスイッチング有効 | D9: Enable_SS | E9: 0 | F9: 0/1 | G9: P_sw低減・追加回路重量増 | H9: 0=無効, 1=有効
A10: 2 | B10: スナバ | C10: スナバ有効 | D10: Enable_snubber | E10: 0 | F10: 0/1 | G10: V_overshoot,P_snub,M_snub | H10: 0=無効、1=有効。Enable_snubberは物理定数ではなくシナリオ選択値。OFF/ON差分で効果を評価する。
A11: 3 | B11: PWM | C11: DPWM有効 | D11: Enable_DPWM | E11: 0 | F11: 0/1 | G11: P_sw,M_DPWM_penalty | H11: 0=無効、1=有効。Enable_DPWMは物理定数ではなくシナリオ選択値。OFF/ON差分で効果を評価する。
A12: 4 | B12: PWM | C12: CM低減PWM有効 | D12: Enable_CM_PWM | E12: 0 | F12: 0/1 | G12: P_sw,M_CM_filter | H12: 0=無効、1=有効。Enable_CM_PWMは物理定数ではなくシナリオ選択値。OFF/ON差分で効果を評価する。
A13: 5 | B13: DCリンクESL | C13: HFローカルデカップリング有効 | D13: Enable_hf_decouple | E13: 0 | F13: 0/1 | G13: V_overshoot,M_hfcap | H13: 0=無効、1=有効。Enable_hf_decoupleは物理定数ではなくシナリオ選択値。OFF/ON差分で効果を評価する。
A14: 6 | B14: dvdtフィルタ | C14: dv/dtフィルタ有効 | D14: Enable_dvdt_filter | E14: 0 | F14: 0/1 | G14: EMI,M_filter | H14: 0=無効、1=有効。Enable_dvdt_filterは物理定数ではなくシナリオ選択値。OFF/ON差分で効果を評価する。
A15: 7 | B15: CMフィルタ | C15: パッシブCMフィルタ有効 | D15: Enable_CM_filter | E15: 0 | F15: 0/1 | G15: M_CM_passive | H15: 0=無効,1=パッシブLC/Y-cap有効
A16: 8 | B16: EMI/構造 | C16: シールド有効 | D16: Enable_shield | E16: 0 | F16: 0/1 | G16: EMI低減/重量増 | H16: 0=無効、1=有効。Enable_shieldは物理定数ではなくシナリオ選択値。OFF/ON差分で効果を評価する。
A17: 9 | B17: 保護 | C17: アクティブクランプ有効 | D17: Enable_active_clamp | E17: 0 | F17: 0/1 | G17: overshoot/M_clamp | H17: 0=無効、1=有効。Enable_active_clampは物理定数ではなくシナリオ選択値。OFF/ON差分で効果を評価する。
A18: 10 | B18: 絶縁 | C18: 高性能絶縁材有効 | D18: Enable_hi_ins | E18: 0 | F18: 0/1 | G18: clearance/M_ins | H18: 0=無効、1=有効。Enable_hi_insは物理定数ではなくシナリオ選択値。OFF/ON差分で効果を評価する。
A19: 11 | B19: 絶縁 | C19: ポッティング有効 | D19: Enable_potting | E19: 0 | F19: 0/1 | G19: clearance/M_pot/Rth | H19: 0=無効、1=有効。Enable_pottingは物理定数ではなくシナリオ選択値。OFF/ON差分で効果を評価する。
A20: 12 | B20: プリチャージ | C20: プリチャージ有効 | D20: Enable_precharge | E20: 1 | F20: 0/1 | G20: contactor/M_precharge | H20: 0=無効、1=有効。Enable_prechargeは物理定数ではなくシナリオ選択値。OFF/ON差分で効果を評価する。
... A35: 27 | B35: 半導体/CSI | C35: 双方向GaN基板管理回路有効 | D35: Enable_BD_GaN_substrate_management | E35: 0 | F35: 0/1 | G35: m_gate/P_loss | H35: dynamic Ron/基板バイアス対策回路の追加重量・損失を評価

Sheet 11_入力分類一覧
A1: 11_入力分類一覧：全入力の参照元と編集頻度
A4: 分類 | B4: 項目数 | D4: 参照元 | E4: 編集頻度 | F4: 役割
A5: システム要求→自動計算 | B5: 24 | D5: 07_システム要求 | E5: シナリオごと | F5: 上位要求
A6: シナリオ固有手入力 | B6: 20 | D6: 10_シナリオ入力 | E6: シナリオごと | F6: 20項目の技術選択
A7: 基準仕様（シナリオ間固定） | B7: 254 | D7: 09_基準仕様 | E7: 原則固定 | F7: 材料・技術基準
A10: 元行 | B10: 分類 | C10: 仕様 | D10: 変数 | E10: 現在値 | F10: 単位 | G10: 新分類 | H10: 参照元 | I10: ユーザー操作 | J10: 旧入力区分 | K10: 感度対象 | L10: 備考
A11: 5 | B11: システム要求 | C11: 定格出力 | D11: P_out | E11: 100 | F11: kW | G11: システム要求→自動計算 | H11: 07_システム要求 | I11: システム要求のみ編集 | J11: 固定要求 | K11: 対象外 | L11: 上位アプリケーションで決定
A12: 6 | B12: 製品仕様 | C12: DCバス電圧 | D12: V_dc | E12: 800 | F12: V | G12: システム要求→自動計算 | H12: 07_システム要求 | I12: システム要求のみ編集 | J12: 設計変数 | K12: 対象 | L12: 変更余地あり
A13: 7 | B13: 製品仕様 | C13: モータ線間電圧RMS | D13: V_ll | E13: 400 | F13: V | G13: システム要求→自動計算 | H13: 07_システム要求 | I13: システム要求のみ編集 | J13: 設計変数 | K13: 対象 | L13: モータ巻線構成等で変更余地
A14: 8 | B14: 製品仕様 | C14: 力率 | D14: PF | E14: 0.95 | F14: - | G14: システム要求→自動計算 | H14: 07_システム要求 | I14: システム要求のみ編集 | J14: 設計変数 | K14: 対象 | L14: モータ/制御で改善余地
A15: 9 | B15: 製品仕様 | C15: インバータ効率 | D15: eta | E15: 0.97 | F15: - | G15: システム要求→自動計算 | H15: 07_システム要求 | I15: システム要求のみ編集 | J15: 設計変数 | K15: 対象 | L15: 簡易扱い
A16: 10 | B16: 製品仕様 | C16: スイッチング周波数 | D16: f_sw | E16: 16000 | F16: Hz | G16: システム要求→自動計算 | H16: 07_システム要求 | I16: システム要求のみ編集 | J16: 設計変数 | K16: 対象 | L16: 主要トレードオフ
A17: 11 | B17: 製品仕様 | C17: 許容DC電圧リップル率 | D17: r_vdc | E17: 0.05 | F17: - | G17: 基準仕様（シナリオ間固定） | H17: 09_基準仕様 | I17: 通常は編集しない | J17: 設計変数 | K17: 対象
A18: 12 | B18: 製品仕様 | C18: DCリンクバッファ時間 | D18: t_buf | E18: 0.0005 | F18: s | G18: 基準仕様（シナリオ間固定） | H18: 09_基準仕様 | I18: 通常は編集しない | J18: 設計変数 | K18: 対象
A19: 13 | B19: 半導体 | C19: パワーモジュール個数 | D19: N_mod | E19: 6 | F19: 個 | G19: 基準仕様（シナリオ間固定） | H19: 09_基準仕様 | I19: 通常は編集しない | J19: 設計変数 | K19: 対象
A20: 14 | B20: 半導体 | C20: DC電圧→必要耐圧係数 | D20: K_vblk | E20: 1.25 | F20: - | G20: 基準仕様（シナリオ間固定） | H20: 09_基準仕様 | I20: 通常は編集しない | J20: 技術係数 | K20: 対象 | L20: サージ/マージン簡略化
A21: 15 | B21: 半導体 | C21: ドリフト層電界利用率 | D21: k_Euse | E21: 0.72 | F21: - | G21: 基準仕様（シナリオ間固定） | H21: 09_基準仕様 | I21: 通常は編集しない | J21: 技術係数 | K21: 対象
A22: 16 | B22: 半導体 | C22: 材料臨界電界 | D22: E_crit | E22: 250000000 | F22: V/m | G22: 基準仕様（シナリオ間固定） | H22: 09_基準仕様 | I22: 通常は編集しない | J22: 材料 | K22: 対象 | L22: SiC簡易値
A23: 17 | B23: 半導体 | C23: ドリフト層厚余裕係数 | D23: K_tdrift | E23: 1.15 | F23: - | G23: 基準仕様（シナリオ間固定） | H23: 09_基準仕様 | I23: 通常は編集しない | J23: 技術係数 | K23: 対象
A24: 18 | B24: 半導体 | C24: 基準ドーピング濃度 | D24: N_d_ref | E24: 8e+21 | F24: 1/m³ | G24: 基準仕様（シナリオ間固定） | H24: 09_基準仕様 | I24: 通常は編集しない | J24: 材料 | K24: 対象 | L24: 説明用
A25: 19 | B25: 半導体 | C25: 耐圧基準 | D25: V_ref_nd | E25: 1200 | F25: V | G25: 基準仕様（シナリオ間固定） | H25: 09_基準仕様 | I25: 通常は編集しない | J25: 技術係数 | K25: 対象
A26: 20 | B26: 半導体 | C26: ドーピング耐圧指数 | D26: a_nd | E26: 1.2 | F26: - | G26: 基準仕様（シナリオ間固定） | H26: 09_基準仕様 | I26: 通常は編集しない | J26: 技術係数 | K26: 対象 | L26: N∝V^-a
A27: 21 | B27: 半導体 | C27: 電子移動度 | D27: mu_n | E27: 0.08 | F27: m²/(V·s) | G27: 基準仕様（シナリオ間固定） | H27: 09_基準仕様 | I27: 通常は編集しない | J27: 材料 | K27: 対象 | L27: 説明用SiC
A28: 22 | B28: 半導体 | C28: 素電荷 | D28: q_e | E28: 1.602e-19 | F28: C | G28: 基準仕様（シナリオ間固定） | H28: 09_基準仕様 | I28: 通常は編集しない | J28: 固定定数 | K28: 対象外 | L28: 物理定数
A29: 23 | B29: 半導体 | C29: 比オン抵抗補正係数 | D29: K_rsp | E29: 1 | F29: - | G29: 基準仕様（シナリオ間固定） | H29: 09_基準仕様 | I29: 通常は編集しない | J29: 技術係数 | K29: 対象
A30: 24 | B30: 半導体 | C30: セル/コンタクト抵抗面積積 | D30: Rsp_cell | E30: 0.0015 | F30: Ω·mm² | G30: 基準仕様（シナリオ間固定） | H30: 09_基準仕様 | I30: 通常は編集しない | J30: 技術係数 | K30: 対象 | L30: 説明用
A31: 25 | B31: 半導体 | C31: チップ面積 | D31: A_chip | E31: 100 | F31: mm² | G31: 基準仕様（シナリオ間固定） | H31: 09_基準仕様 | I31: 通常は編集しない | J31: 設計変数 | K31: 対象 | L31: 主要トレードオフ
A32: 26 | B32: 半導体 | C32: チップ厚さ | D32: t_chip | E32: 0.18 | F32: mm | G32: 基準仕様（シナリオ間固定） | H32: 09_基準仕様 | I32: 通常は編集しない | J32: 設計変数 | K32: 対象
A33: 27 | B33: 半導体 | C33: チップ密度 | D33: rho_chip | E33: 3210 | F33: kg/m³ | G33: 基準仕様（シナリオ間固定） | H33: 09_基準仕様 | I33: 通常は編集しない | J33: 材料 | K33: 対象 | L33: SiC
A34: 28 | B34: 半導体 | C34: 出力容量面積係数 | D34: Coss_area_ref | E34: 0.55 | F34: nF/mm² | G34: 基準仕様（シナリオ間固定） | H34: 09_基準仕様 | I34: 通常は編集しない | J34: 技術係数 | K34: 対象 | L34: 説明用
A35: 29 | B35: 半導体 | C35: 容量耐圧指数 | D35: b_coss | E35: 0.35 | F35: - | G35: 基準仕様（シナリオ間固定） | H35: 09_基準仕様 | I35: 通常は編集しない | J35: 技術係数 | K35: 対象 | L35: Coss∝V^-b
A36: 30 | B36: 半導体 | C36: 容量耐圧基準 | D36: V_ref_coss | E36: 1200 | F36: V | G36: 基準仕様（シナリオ間固定） | H36: 09_基準仕様 | I36: 通常は編集しない | J36: 技術係数 | K36: 対象
A37: 31 | B37: 半導体 | C37: スイッチングエネルギー容量係数 | D37: K_esw | E37: 1 | F37: - | G37: 基準仕様（シナリオ間固定） | H37: 09_基準仕様 | I37: 通常は編集しない | J37: 技術係数 | K37: 対象 | L37: 0.5CV²簡略化
A38: 32 | B38: 半導体 | C38: チップ数係数 | D38: k_chip | E38: 1.25 | F38: - | G38: 基準仕様（シナリオ間固定） | H38: 09_基準仕様 | I38: 通常は編集しない | J38: 技術係数 | K38: 対象
A39: 33 | B39: 半導体 | C39: チップ許容電流密度 | D39: J_chip | E39: 1.15 | F39: A/mm² | G39: 基準仕様（シナリオ間固定） | H39: 09_基準仕様 | I39: 通常は編集しない | J39: 設計変数 | K39: 対象
A40: 34 | B40: 半導体 | C40: チップ有効面積率 | D40: k_active | E40: 0.72 | F40: - | G40: 基準仕様（シナリオ間固定） | H40: 09_基準仕様 | I40: 通常は編集しない | J40: 技術係数 | K40: 対象
A41: 35 | B41: 半導体 | C41: DBC面積 | D41: A_dbc | E41: 4200 | F41: mm² | G41: 基準仕様（シナリオ間固定） | H41: 09_基準仕様 | I41: 通常は編集しない | J41: 設計変数 | K41: 対象
A42: 36 | B42: 半導体 | C42: DBC等価厚さ | D42: t_dbc | E42: 0.92 | F42: mm | G42: 基準仕様（シナリオ間固定） | H42: 09_基準仕様 | I42: 通常は編集しない | J42: 設計変数 | K42: 対象
A43: 37 | B43: 半導体 | C43: DBC等価密度 | D43: rho_dbc | E43: 4000 | F43: kg/m³ | G43: 基準仕様（シナリオ間固定） | H43: 09_基準仕様 | I43: 通常は編集しない | J43: 材料 | K43: 対象
A44: 38 | B44: 半導体 | C44: ベース面積 | D44: A_base | E44: 5000 | F44: mm² | G44: 基準仕様（シナリオ間固定） | H44: 09_基準仕様 | I44: 通常は編集しない | J44: 設計変数 | K44: 対象
...

Sheet 14_研究要素評価
A1: 研究ID | B1: 研究要素（パワエレ技術者向け説明名） | C1: 研究目的 | D1: 影響変数数 | E1: 重量低減ポテンシャル [kg-eq] | F1: 出口戦略指数 [0-100] | G1: 重量低減ポテンシャル順位 | H1: 参照状態／注意 | I1: 参照済変数数 | J1: モデル接続率 | K1: モデル化状態 | L1: 研究カテゴリ | M1: 主適用領域 | N1: 代表文献ID
A2: R001 | B2: 高耐圧・低オン抵抗・低出力容量を両立する次世代パワー半導体 | C2: 高Vdc化で増える耐圧・導通損失・スイッチング損失の重量ペナルティを抑える | D2: =COUNTIF('15_研究変数マップ'!$A$2:$A$189,A2) -> 5 | E2: =SUMIF('15_研究変数マップ'!$A$2:$A$189,A2,'15_研究変数マップ'!$H$2:$H$189) -> 4 | F2: =IF(MAX($D$2:$D$41)=0,0,D2/MAX($D$2:$D$41)*100) -> 25 | G2: =IF(E2="","",_xludf.RANK.EQ(E2,$E$2:$E$41,0)) -> #NAME? | H2: 数値は15_研究変数マップを参照。kg-eqは局所感度ベースのスクリーニング値であり、実Δkgではない。 | I2: =COUNTIFS('15_研究変数マップ'!$A$2:$A$189,A2,'15_研究変数マップ'!$I$2:$I$189,"参照済") -> 5 | J2: =IF(D2=0,0,I2/D2) -> 1 | K2: =IF(I2=0,"未接続",IF(I2<D2,"部分接続","接続済")) -> 接続済 | L2: 既存研究要素 | M2: 既存版で定義
